[3J[H[2J[94mℹ️ Bilgi: Runner başlatılıyor...[0m
[94mℹ️ Bilgi: İnternet bağlantısı kontrol ediliyor...[0m
[92m✔️ Başarı: İnternet bağlantısı başarılı.[0m
[94mℹ️ Bilgi: DNS sunucusu kontrol ediliyor...[0m
[92m✔️ Başarı: DNS sunucusu başarılı.[0m
[94mℹ️ Bilgi: MongoDB Bağlantı Bilgileri:[0m
[94mℹ️ Bilgi:   URI: mongodb+srv://User:kwn7FYK5nvh9pnbcbc@autospd.mkvab.mongodb.net/?retryWrites=true&w=majority&authSource=admin&appName=AutoSPD[0m
[94mℹ️ Bilgi:   Veritabanı: AutoSPD[0m
[92m✔️ Başarı: MongoDB bağlantısı başarılı.[0m
[94mℹ️ Bilgi: SQLite Bağlantı Bilgileri:[0m
[94mℹ️ Bilgi:   Veritabanı Dosyası: state.db[0m
[92m✔️ Başarı: SQLite bağlantısı başarılı.[0m
[94mℹ️ Bilgi: PostgreSQL Bağlantı Bilgileri:[0m
[94mℹ️ Bilgi:   Kullanıcı: postgres[0m
[94mℹ️ Bilgi:   Veritabanı: AntiSpam[0m
[94mℹ️ Bilgi:   Sunucu: 178.20.231.247[0m
[94mℹ️ Bilgi:   Port: 5432[0m
[92m✔️ Başarı: PostgreSQL bağlantısı başarılı.[0m
[94mℹ️ Bilgi: RabbitMQ Bağlantı Bilgileri:[0m
[94mℹ️ Bilgi:   Host: 178.20.231.247[0m
[94mℹ️ Bilgi:   Port: 5672[0m
[94mℹ️ Bilgi:   Kullanıcı Adı: admin[0m
[92m✔️ Başarı: RabbitMQ bağlantısı başarılı.[0m
[94mℹ️ Bilgi: Spamhaus (zen.spamhaus.org) kontrol ediliyor...[0m
[94mℹ️ Bilgi: Spamhaus (zen.spamhaus.org): IP kara listede değil.[0m
[94mℹ️ Bilgi: Barracuda (b.barracudacentral.org) kontrol ediliyor...[0m
[94mℹ️ Bilgi: Barracuda (b.barracudacentral.org): IP kara listede değil.[0m
[94mℹ️ Bilgi: SORBS (dnsbl.sorbs.net) kontrol ediliyor...[0m
[94mℹ️ Bilgi: SORBS (dnsbl.sorbs.net): IP kara listede değil.[0m
[94mℹ️ Bilgi: SpamCop (bl.spamcop.net) kontrol ediliyor...[0m
[94mℹ️ Bilgi: SpamCop (bl.spamcop.net): IP kara listede değil.[0m
[94mℹ️ Bilgi: The CBL (cbl.abuseat.org) kontrol ediliyor...[0m
[94mℹ️ Bilgi: The CBL (cbl.abuseat.org): IP kara listede değil.[0m
[94mℹ️ Bilgi: SURBL (multi.uribl.com) kontrol ediliyor...[0m
[92m✔️ Başarı: SURBL (multi.uribl.com) IP kara listede. Yanıt süresi: 218.16 ms[0m
[94mℹ️ Bilgi: MultiRBL (multi.surbl.org) kontrol ediliyor...[0m
[94mℹ️ Bilgi: MultiRBL (multi.surbl.org): IP kara listede değil.[0m
[94mℹ️ Bilgi: Hostkarma (karma.junkemailfilter.com) kontrol ediliyor...[0m
[94mℹ️ Bilgi: Hostkarma (karma.junkemailfilter.com): IP kara listede değil.[0m
[94mℹ️ Bilgi: Spamhaus DROP (drop.spamhaus.org) kontrol ediliyor...[0m
[94mℹ️ Bilgi: Spamhaus DROP (drop.spamhaus.org): IP kara listede değil.[0m
[94mℹ️ Bilgi: Spamhaus EDROP (edrop.spamhaus.org) kontrol ediliyor...[0m
[94mℹ️ Bilgi: Spamhaus EDROP (edrop.spamhaus.org): IP kara listede değil.[0m
[94mℹ️ Bilgi: Karaliste Sağlık Kontrol Sonuçları:[0m
[93m⚠️ Uyarı: Spamhaus: IP kara listede değil (Hata: Belirtilmedi)[0m
[93m⚠️ Uyarı: Barracuda: IP kara listede değil (Hata: Belirtilmedi)[0m
[93m⚠️ Uyarı: SORBS: IP kara listede değil (Hata: Belirtilmedi)[0m
[93m⚠️ Uyarı: SpamCop: IP kara listede değil (Hata: Belirtilmedi)[0m
[93m⚠️ Uyarı: The CBL: IP kara listede değil (Hata: Belirtilmedi)[0m
[94mℹ️ Bilgi: SURBL: IP kara listede - 218.16 ms[0m
[93m⚠️ Uyarı: MultiRBL: IP kara listede değil (Hata: Belirtilmedi)[0m
[93m⚠️ Uyarı: Hostkarma: IP kara listede değil (Hata: Belirtilmedi)[0m
[93m⚠️ Uyarı: Spamhaus DROP: IP kara listede değil (Hata: Belirtilmedi)[0m
[93m⚠️ Uyarı: Spamhaus EDROP: IP kara listede değil (Hata: Belirtilmedi)[0m
[92m✔️ Başarı: Tüm testler tamamlandı.[0m
[94mℹ️ Bilgi: İş akışı için görevleri kontrol ediyorum...[0m
[92m✔️ Başarı: SQLite gerekli tablolar başarıyla oluşturuldu.[0m
[92m✔️ Başarı: PostgreSQL gerekli tablolar başarıyla oluşturuldu.[0m
[92m✔️ Başarı: RabbitMQ kuyruğu oluşturuldu ve temizlendi.[0m
[92m✔️ Başarı: SQLite eski kayıtlar temizlendi.[0m
[94mℹ️ Bilgi: Bugünkü pending görevler bulundu.[0m
[92m✔️ Başarı: Görevler RabbitMQ'ya senkronize edildi.[0m
[94mℹ️ Bilgi: Pending görevler RabbitMQ'ya senkronize edildi.[0m
[94mℹ️ Bilgi: Görev işleniyor: !!python/tuple
- 213
- 37.123.97.22
- SORBS
- dnsbl.sorbs.net
- pending
- '2024-12-04'
[0m
[94mℹ️ Bilgi: IP kara listede değil, kayıt yapılmayacak.[0m
[94mℹ️ Bilgi: Görev işleniyor: !!python/tuple
- 214
- 37.123.97.22
- SpamCop
- bl.spamcop.net
- pending
- '2024-12-04'
[0m
[94mℹ️ Bilgi: IP kara listede değil, kayıt yapılmayacak.[0m
[94mℹ️ Bilgi: Görev işleniyor: !!python/tuple
- 215
- 37.123.97.22
- The CBL
- cbl.abuseat.org
- pending
- '2024-12-04'
[0m
[94mℹ️ Bilgi: IP kara listede değil, kayıt yapılmayacak.[0m
[94mℹ️ Bilgi: Görev işleniyor: !!python/tuple
- 216
- 37.123.97.22
- SURBL
- multi.uribl.com
- pending
- '2024-12-04'
[0m
[94mℹ️ Bilgi: IP kara listede değil, kayıt yapılmayacak.[0m
[94mℹ️ Bilgi: Görev işleniyor: !!python/tuple
- 217
- 37.123.97.22
- MultiRBL
- multi.surbl.org
- pending
- '2024-12-04'
[0m
[94mℹ️ Bilgi: IP kara listede değil, kayıt yapılmayacak.[0m
[94mℹ️ Bilgi: Görev işleniyor: !!python/tuple
- 218
- 37.123.97.22
- Hostkarma
- karma.junkemailfilter.com
- pending
- '2024-12-04'
[0m
[94mℹ️ Bilgi: IP kara listede değil, kayıt yapılmayacak.[0m
[94mℹ️ Bilgi: Görev işleniyor: !!python/tuple
- 219
- 37.123.97.22
- Spamhaus DROP
- drop.spamhaus.org
- pending
- '2024-12-04'
[0m
[94mℹ️ Bilgi: IP kara listede değil, kayıt yapılmayacak.[0m
[94mℹ️ Bilgi: Görev işleniyor: !!python/tuple
- 220
- 37.123.97.22
- Spamhaus EDROP
- edrop.spamhaus.org
- pending
- '2024-12-04'
[0m
[94mℹ️ Bilgi: IP kara listede değil, kayıt yapılmayacak.[0m
[94mℹ️ Bilgi: Görev işleniyor: !!python/tuple
- 221
- 37.123.97.23
- Spamhaus
- zen.spamhaus.org
- pending
- '2024-12-04'
[0m
[94mℹ️ Bilgi: IP kara listede değil, kayıt yapılmayacak.[0m
[94mℹ️ Bilgi: Görev işleniyor: !!python/tuple
- 222
- 37.123.97.23
- Barracuda
- b.barracudacentral.org
- pending
- '2024-12-04'
[0m
[94mℹ️ Bilgi: IP kara listede değil, kayıt yapılmayacak.[0m
[94mℹ️ Bilgi: Görev işleniyor: !!python/tuple
- 223
- 37.123.97.23
- SORBS
- dnsbl.sorbs.net
- pending
- '2024-12-04'
[0m
[94mℹ️ Bilgi: IP kara listede değil, kayıt yapılmayacak.[0m
[94mℹ️ Bilgi: Görev işleniyor: !!python/tuple
- 224
- 37.123.97.23
- SpamCop
- bl.spamcop.net
- pending
- '2024-12-04'
[0m
[94mℹ️ Bilgi: IP kara listede değil, kayıt yapılmayacak.[0m
[94mℹ️ Bilgi: Görev işleniyor: !!python/tuple
- 225
- 37.123.97.23
- The CBL
- cbl.abuseat.org
- pending
- '2024-12-04'
[0m
[94mℹ️ Bilgi: IP kara listede değil, kayıt yapılmayacak.[0m
[94mℹ️ Bilgi: Görev işleniyor: !!python/tuple
- 226
- 37.123.97.23
- SURBL
- multi.uribl.com
- pending
- '2024-12-04'
[0m
[94mℹ️ Bilgi: IP kara listede değil, kayıt yapılmayacak.[0m
[94mℹ️ Bilgi: Görev işleniyor: !!python/tuple
- 227
- 37.123.97.23
- MultiRBL
- multi.surbl.org
- pending
- '2024-12-04'
[0m
[94mℹ️ Bilgi: IP kara listede değil, kayıt yapılmayacak.[0m
[94mℹ️ Bilgi: Görev işleniyor: !!python/tuple
- 228
- 37.123.97.23
- Hostkarma
- karma.junkemailfilter.com
- pending
- '2024-12-04'
[0m
[94mℹ️ Bilgi: IP kara listede değil, kayıt yapılmayacak.[0m
[94mℹ️ Bilgi: Görev işleniyor: !!python/tuple
- 229
- 37.123.97.23
- Spamhaus DROP
- drop.spamhaus.org
- pending
- '2024-12-04'
[0m
[94mℹ️ Bilgi: IP kara listede değil, kayıt yapılmayacak.[0m
[94mℹ️ Bilgi: Görev işleniyor: !!python/tuple
- 230
- 37.123.97.23
- Spamhaus EDROP
- edrop.spamhaus.org
- pending
- '2024-12-04'
[0m
[94mℹ️ Bilgi: IP kara listede değil, kayıt yapılmayacak.[0m
[94mℹ️ Bilgi: Görev işleniyor: !!python/tuple
- 231
- 37.123.97.24
- Spamhaus
- zen.spamhaus.org
- pending
- '2024-12-04'
[0m
[94mℹ️ Bilgi: IP kara listede değil, kayıt yapılmayacak.[0m
Exception in thread Thread-4 (task):
Traceback (most recent call last):
  File "/opt/homebrew/Cellar/python@3.10/3.10.15/Frameworks/Python.framework/Versions/3.10/lib/python3.10/threading.py", line 1016, in _bootstrap_inner
    self.run()
  File "/opt/homebrew/Cellar/python@3.10/3.10.15/Frameworks/Python.framework/Versions/3.10/lib/python3.10/threading.py", line 953, in run
    self._target(*self._args, **self._kwargs)
  File "/Users/admin/Desktop/Github/SPDApiNetwork/tools/blacklist2/query.py", line 22, in task
    cursor.execute(
psycopg2.errors.UndefinedTable: relation "blacklisted_ips" does not exist
LINE 1: SELECT * FROM blacklisted_ips WHERE ip = '37.123.97.22' AND ...
                      ^

Exception in thread Thread-5 (task):
Traceback (most recent call last):
  File "/opt/homebrew/Cellar/python@3.10/3.10.15/Frameworks/Python.framework/Versions/3.10/lib/python3.10/threading.py", line 1016, in _bootstrap_inner
    self.run()
  File "/opt/homebrew/Cellar/python@3.10/3.10.15/Frameworks/Python.framework/Versions/3.10/lib/python3.10/threading.py", line 953, in run
    self._target(*self._args, **self._kwargs)
  File "/Users/admin/Desktop/Github/SPDApiNetwork/tools/blacklist2/query.py", line 22, in task
    cursor.execute(
psycopg2.errors.UndefinedTable: relation "blacklisted_ips" does not exist
LINE 1: SELECT * FROM blacklisted_ips WHERE ip = '37.123.97.22' AND ...
                      ^

Exception in thread Thread-8 (task):
Traceback (most recent call last):
  File "/opt/homebrew/Cellar/python@3.10/3.10.15/Frameworks/Python.framework/Versions/3.10/lib/python3.10/threading.py", line 1016, in _bootstrap_inner
    self.run()
  File "/opt/homebrew/Cellar/python@3.10/3.10.15/Frameworks/Python.framework/Versions/3.10/lib/python3.10/threading.py", line 953, in run
    self._target(*self._args, **self._kwargs)
  File "/Users/admin/Desktop/Github/SPDApiNetwork/tools/blacklist2/query.py", line 22, in task
    cursor.execute(
psycopg2.errors.UndefinedTable: relation "blacklisted_ips" does not exist
LINE 1: SELECT * FROM blacklisted_ips WHERE ip = '37.123.97.22' AND ...
                      ^

Exception in thread Thread-9 (task):
Traceback (most recent call last):
  File "/opt/homebrew/Cellar/python@3.10/3.10.15/Frameworks/Python.framework/Versions/3.10/lib/python3.10/threading.py", line 1016, in _bootstrap_inner
    self.run()
  File "/opt/homebrew/Cellar/python@3.10/3.10.15/Frameworks/Python.framework/Versions/3.10/lib/python3.10/threading.py", line 953, in run
    self._target(*self._args, **self._kwargs)
  File "/Users/admin/Desktop/Github/SPDApiNetwork/tools/blacklist2/query.py", line 22, in task
    cursor.execute(
psycopg2.errors.UndefinedTable: relation "blacklisted_ips" does not exist
LINE 1: SELECT * FROM blacklisted_ips WHERE ip = '37.123.97.22' AND ...
                      ^

Exception in thread Thread-10 (task):
Traceback (most recent call last):
  File "/opt/homebrew/Cellar/python@3.10/3.10.15/Frameworks/Python.framework/Versions/3.10/lib/python3.10/threading.py", line 1016, in _bootstrap_inner
    self.run()
  File "/opt/homebrew/Cellar/python@3.10/3.10.15/Frameworks/Python.framework/Versions/3.10/lib/python3.10/threading.py", line 953, in run
    self._target(*self._args, **self._kwargs)
  File "/Users/admin/Desktop/Github/SPDApiNetwork/tools/blacklist2/query.py", line 22, in task
    cursor.execute(
psycopg2.errors.UndefinedTable: relation "blacklisted_ips" does not exist
LINE 1: SELECT * FROM blacklisted_ips WHERE ip = '37.123.97.22' AND ...
                      ^

Exception in thread Thread-11 (task):
Traceback (most recent call last):
  File "/opt/homebrew/Cellar/python@3.10/3.10.15/Frameworks/Python.framework/Versions/3.10/lib/python3.10/threading.py", line 1016, in _bootstrap_inner
    self.run()
  File "/opt/homebrew/Cellar/python@3.10/3.10.15/Frameworks/Python.framework/Versions/3.10/lib/python3.10/threading.py", line 953, in run
    self._target(*self._args, **self._kwargs)
  File "/Users/admin/Desktop/Github/SPDApiNetwork/tools/blacklist2/query.py", line 22, in task
    cursor.execute(
psycopg2.errors.UndefinedTable: relation "blacklisted_ips" does not exist
LINE 1: SELECT * FROM blacklisted_ips WHERE ip = '37.123.97.22' AND ...
                      ^

[94mℹ️ Bilgi: Görev işleniyor: !!python/tuple
- 232
- 37.123.97.24
- Barracuda
- b.barracudacentral.org
- pending
- '2024-12-04'
[0m
[94mℹ️ Bilgi: IP kara listede değil, kayıt yapılmayacak.[0m
[94mℹ️ Bilgi: Görev işleniyor: !!python/tuple
- 233
- 37.123.97.24
- SORBS
- dnsbl.sorbs.net
- pending
- '2024-12-04'
[0m
[94mℹ️ Bilgi: IP kara listede değil, kayıt yapılmayacak.[0m
[94mℹ️ Bilgi: Görev işleniyor: !!python/tuple
- 234
- 37.123.97.24
- SpamCop
- bl.spamcop.net
- pending
- '2024-12-04'
[0m
[94mℹ️ Bilgi: IP kara listede değil, kayıt yapılmayacak.[0m
[94mℹ️ Bilgi: Görev işleniyor: !!python/tuple
- 235
- 37.123.97.24
- The CBL
- cbl.abuseat.org
- pending
- '2024-12-04'
[0m
[94mℹ️ Bilgi: IP kara listede değil, kayıt yapılmayacak.[0m
[94mℹ️ Bilgi: Görev işleniyor: !!python/tuple
- 236
- 37.123.97.24
- SURBL
- multi.uribl.com
- pending
- '2024-12-04'
[0m
[94mℹ️ Bilgi: IP kara listede değil, kayıt yapılmayacak.[0m
[94mℹ️ Bilgi: Görev işleniyor: !!python/tuple
- 237
- 37.123.97.24
- MultiRBL
- multi.surbl.org
- pending
- '2024-12-04'
[0m
[94mℹ️ Bilgi: IP kara listede değil, kayıt yapılmayacak.[0m
[94mℹ️ Bilgi: Görev işleniyor: !!python/tuple
- 238
- 37.123.97.24
- Hostkarma
- karma.junkemailfilter.com
- pending
- '2024-12-04'
[0m
[94mℹ️ Bilgi: IP kara listede değil, kayıt yapılmayacak.[0m
[94mℹ️ Bilgi: Görev işleniyor: !!python/tuple
- 239
- 37.123.97.24
- Spamhaus DROP
- drop.spamhaus.org
- pending
- '2024-12-04'
[0m
[94mℹ️ Bilgi: IP kara listede değil, kayıt yapılmayacak.[0m
[94mℹ️ Bilgi: Görev işleniyor: !!python/tuple
- 240
- 37.123.97.24
- Spamhaus EDROP
- edrop.spamhaus.org
- pending
- '2024-12-04'
[0m
[94mℹ️ Bilgi: IP kara listede değil, kayıt yapılmayacak.[0m
[94mℹ️ Bilgi: Görev işleniyor: !!python/tuple
- 241
- 37.123.97.25
- Spamhaus
- zen.spamhaus.org
- pending
- '2024-12-04'
[0m
[94mℹ️ Bilgi: IP kara listede değil, kayıt yapılmayacak.[0m
[94mℹ️ Bilgi: Görev işleniyor: !!python/tuple
- 242
- 37.123.97.25
- Barracuda
- b.barracudacentral.org
- pending
- '2024-12-04'
[0m
[94mℹ️ Bilgi: IP kara listede değil, kayıt yapılmayacak.[0m
[94mℹ️ Bilgi: Görev işleniyor: !!python/tuple
- 243
- 37.123.97.25
- SORBS
- dnsbl.sorbs.net
- pending
- '2024-12-04'
[0m
[94mℹ️ Bilgi: IP kara listede değil, kayıt yapılmayacak.[0m
[94mℹ️ Bilgi: Görev işleniyor: !!python/tuple
- 244
- 37.123.97.25
- SpamCop
- bl.spamcop.net
- pending
- '2024-12-04'
[0m
[94mℹ️ Bilgi: IP kara listede değil, kayıt yapılmayacak.[0m
[94mℹ️ Bilgi: Görev işleniyor: !!python/tuple
- 245
- 37.123.97.25
- The CBL
- cbl.abuseat.org
- pending
- '2024-12-04'
[0m
[94mℹ️ Bilgi: IP kara listede değil, kayıt yapılmayacak.[0m
[94mℹ️ Bilgi: Görev işleniyor: !!python/tuple
- 246
- 37.123.97.25
- SURBL
- multi.uribl.com
- pending
- '2024-12-04'
[0m
[94mℹ️ Bilgi: IP kara listede değil, kayıt yapılmayacak.[0m
[94mℹ️ Bilgi: Görev işleniyor: !!python/tuple
- 247
- 37.123.97.25
- MultiRBL
- multi.surbl.org
- pending
- '2024-12-04'
[0m
[94mℹ️ Bilgi: IP kara listede değil, kayıt yapılmayacak.[0m
[94mℹ️ Bilgi: Görev işleniyor: !!python/tuple
- 248
- 37.123.97.25
- Hostkarma
- karma.junkemailfilter.com
- pending
- '2024-12-04'
[0m
[94mℹ️ Bilgi: IP kara listede değil, kayıt yapılmayacak.[0m
[94mℹ️ Bilgi: Görev işleniyor: !!python/tuple
- 249
- 37.123.97.25
- Spamhaus DROP
- drop.spamhaus.org
- pending
- '2024-12-04'
[0m
[94mℹ️ Bilgi: IP kara listede değil, kayıt yapılmayacak.[0m
[94mℹ️ Bilgi: Görev işleniyor: !!python/tuple
- 250
- 37.123.97.25
- Spamhaus EDROP
- edrop.spamhaus.org
- pending
- '2024-12-04'
[0m
[94mℹ️ Bilgi: IP kara listede değil, kayıt yapılmayacak.[0m
[94mℹ️ Bilgi: Görev işleniyor: !!python/tuple
- 251
- 37.123.97.26
- Spamhaus
- zen.spamhaus.org
- pending
- '2024-12-04'
[0m
[94mℹ️ Bilgi: IP kara listede değil, kayıt yapılmayacak.[0m
[94mℹ️ Bilgi: Görev işleniyor: !!python/tuple
- 252
- 37.123.97.26
- Barracuda
- b.barracudacentral.org
- pending
- '2024-12-04'
[0m
[94mℹ️ Bilgi: IP kara listede değil, kayıt yapılmayacak.[0m
[94mℹ️ Bilgi: Görev işleniyor: !!python/tuple
- 253
- 37.123.97.26
- SORBS
- dnsbl.sorbs.net
- pending
- '2024-12-04'
[0m
[94mℹ️ Bilgi: IP kara listede değil, kayıt yapılmayacak.[0m
[94mℹ️ Bilgi: Görev işleniyor: !!python/tuple
- 254
- 37.123.97.26
- SpamCop
- bl.spamcop.net
- pending
- '2024-12-04'
[0m
[94mℹ️ Bilgi: IP kara listede değil, kayıt yapılmayacak.[0m
[94mℹ️ Bilgi: Görev işleniyor: !!python/tuple
- 255
- 37.123.97.26
- The CBL
- cbl.abuseat.org
- pending
- '2024-12-04'
[0m
[94mℹ️ Bilgi: IP kara listede değil, kayıt yapılmayacak.[0m
[94mℹ️ Bilgi: Görev işleniyor: !!python/tuple
- 256
- 37.123.97.26
- SURBL
- multi.uribl.com
- pending
- '2024-12-04'
[0m
[94mℹ️ Bilgi: IP kara listede değil, kayıt yapılmayacak.[0m
[94mℹ️ Bilgi: Görev işleniyor: !!python/tuple
- 257
- 37.123.97.26
- MultiRBL
- multi.surbl.org
- pending
- '2024-12-04'
[0m
[94mℹ️ Bilgi: IP kara listede değil, kayıt yapılmayacak.[0m
[94mℹ️ Bilgi: Görev işleniyor: !!python/tuple
- 258
- 37.123.97.26
- Hostkarma
- karma.junkemailfilter.com
- pending
- '2024-12-04'
[0m
[94mℹ️ Bilgi: IP kara listede değil, kayıt yapılmayacak.[0m
[94mℹ️ Bilgi: Görev işleniyor: !!python/tuple
- 259
- 37.123.97.26
- Spamhaus DROP
- drop.spamhaus.org
- pending
- '2024-12-04'
[0m
[94mℹ️ Bilgi: IP kara listede değil, kayıt yapılmayacak.[0m
[94mℹ️ Bilgi: Görev işleniyor: !!python/tuple
- 260
- 37.123.97.26
- Spamhaus EDROP
- edrop.spamhaus.org
- pending
- '2024-12-04'
[0m
[94mℹ️ Bilgi: IP kara listede değil, kayıt yapılmayacak.[0m
[94mℹ️ Bilgi: Görev işleniyor: !!python/tuple
- 261
- 37.123.97.27
- Spamhaus
- zen.spamhaus.org
- pending
- '2024-12-04'
[0m
[94mℹ️ Bilgi: IP kara listede değil, kayıt yapılmayacak.[0m
[94mℹ️ Bilgi: Görev işleniyor: !!python/tuple
- 262
- 37.123.97.27
- Barracuda
- b.barracudacentral.org
- pending
- '2024-12-04'
[0m
[94mℹ️ Bilgi: IP kara listede değil, kayıt yapılmayacak.[0m
[94mℹ️ Bilgi: Görev işleniyor: !!python/tuple
- 263
- 37.123.97.27
- SORBS
- dnsbl.sorbs.net
- pending
- '2024-12-04'
[0m
[94mℹ️ Bilgi: IP kara listede değil, kayıt yapılmayacak.[0m
[94mℹ️ Bilgi: Görev işleniyor: !!python/tuple
- 264
- 37.123.97.27
- SpamCop
- bl.spamcop.net
- pending
- '2024-12-04'
[0m
[94mℹ️ Bilgi: IP kara listede değil, kayıt yapılmayacak.[0m
[94mℹ️ Bilgi: Görev işleniyor: !!python/tuple
- 265
- 37.123.97.27
- The CBL
- cbl.abuseat.org
- pending
- '2024-12-04'
[0m
[94mℹ️ Bilgi: IP kara listede değil, kayıt yapılmayacak.[0m
[94mℹ️ Bilgi: Görev işleniyor: !!python/tuple
- 266
- 37.123.97.27
- SURBL
- multi.uribl.com
- pending
- '2024-12-04'
[0m
[94mℹ️ Bilgi: IP kara listede değil, kayıt yapılmayacak.[0m
[94mℹ️ Bilgi: Görev işleniyor: !!python/tuple
- 267
- 37.123.97.27
- MultiRBL
- multi.surbl.org
- pending
- '2024-12-04'
[0m
[94mℹ️ Bilgi: IP kara listede değil, kayıt yapılmayacak.[0m
[94mℹ️ Bilgi: Görev işleniyor: !!python/tuple
- 268
- 37.123.97.27
- Hostkarma
- karma.junkemailfilter.com
- pending
- '2024-12-04'
[0m
[94mℹ️ Bilgi: IP kara listede değil, kayıt yapılmayacak.[0m
[94mℹ️ Bilgi: Görev işleniyor: !!python/tuple
- 269
- 37.123.97.27
- Spamhaus DROP
- drop.spamhaus.org
- pending
- '2024-12-04'
[0m
[94mℹ️ Bilgi: IP kara listede değil, kayıt yapılmayacak.[0m
[94mℹ️ Bilgi: Görev işleniyor: !!python/tuple
- 270
- 37.123.97.27
- Spamhaus EDROP
- edrop.spamhaus.org
- pending
- '2024-12-04'
[0m
[94mℹ️ Bilgi: IP kara listede değil, kayıt yapılmayacak.[0m
[94mℹ️ Bilgi: Görev işleniyor: !!python/tuple
- 271
- 37.123.97.28
- Spamhaus
- zen.spamhaus.org
- pending
- '2024-12-04'
[0m
[94mℹ️ Bilgi: IP kara listede değil, kayıt yapılmayacak.[0m
Exception in thread Thread-12 (task):
Traceback (most recent call last):
  File "/opt/homebrew/Cellar/python@3.10/3.10.15/Frameworks/Python.framework/Versions/3.10/lib/python3.10/threading.py", line 1016, in _bootstrap_inner
    self.run()
  File "/opt/homebrew/Cellar/python@3.10/3.10.15/Frameworks/Python.framework/Versions/3.10/lib/python3.10/threading.py", line 953, in run
    self._target(*self._args, **self._kwargs)
  File "/Users/admin/Desktop/Github/SPDApiNetwork/tools/blacklist2/query.py", line 22, in task
    cursor.execute(
psycopg2.errors.UndefinedTable: relation "blacklisted_ips" does not exist
LINE 1: SELECT * FROM blacklisted_ips WHERE ip = '37.123.97.23' AND ...
                      ^

Exception in thread Thread-13 (task):
Traceback (most recent call last):
  File "/opt/homebrew/Cellar/python@3.10/3.10.15/Frameworks/Python.framework/Versions/3.10/lib/python3.10/threading.py", line 1016, in _bootstrap_inner
    self.run()
  File "/opt/homebrew/Cellar/python@3.10/3.10.15/Frameworks/Python.framework/Versions/3.10/lib/python3.10/threading.py", line 953, in run
    self._target(*self._args, **self._kwargs)
  File "/Users/admin/Desktop/Github/SPDApiNetwork/tools/blacklist2/query.py", line 22, in task
    cursor.execute(
psycopg2.errors.UndefinedTable: relation "blacklisted_ips" does not exist
LINE 1: SELECT * FROM blacklisted_ips WHERE ip = '37.123.97.23' AND ...
                      ^

Exception in thread Thread-14 (task):
Traceback (most recent call last):
  File "/opt/homebrew/Cellar/python@3.10/3.10.15/Frameworks/Python.framework/Versions/3.10/lib/python3.10/threading.py", line 1016, in _bootstrap_inner
    self.run()
  File "/opt/homebrew/Cellar/python@3.10/3.10.15/Frameworks/Python.framework/Versions/3.10/lib/python3.10/threading.py", line 953, in run
    self._target(*self._args, **self._kwargs)
  File "/Users/admin/Desktop/Github/SPDApiNetwork/tools/blacklist2/query.py", line 22, in task
    cursor.execute(
psycopg2.errors.UndefinedTable: relation "blacklisted_ips" does not exist
LINE 1: SELECT * FROM blacklisted_ips WHERE ip = '37.123.97.23' AND ...
                      ^

Exception in thread Thread-16 (task):
Traceback (most recent call last):
Exception in thread Thread-7 (task):
Traceback (most recent call last):
  File "/opt/homebrew/Cellar/python@3.10/3.10.15/Frameworks/Python.framework/Versions/3.10/lib/python3.10/threading.py", line 1016, in _bootstrap_inner
Exception in thread Thread-22 (task):
Traceback (most recent call last):
  File "/opt/homebrew/Cellar/python@3.10/3.10.15/Frameworks/Python.framework/Versions/3.10/lib/python3.10/threading.py", line 1016, in _bootstrap_inner
Exception in thread Thread-25 (task):
Traceback (most recent call last):
Exception in thread Thread-27 (task):
Traceback (most recent call last):
Exception in thread Thread-20 (task):
Traceback (most recent call last):
  File "/opt/homebrew/Cellar/python@3.10/3.10.15/Frameworks/Python.framework/Versions/3.10/lib/python3.10/threading.py", line 1016, in _bootstrap_inner
Exception in thread Thread-26 (task):
Traceback (most recent call last):
  File "/opt/homebrew/Cellar/python@3.10/3.10.15/Frameworks/Python.framework/Versions/3.10/lib/python3.10/threading.py", line 1016, in _bootstrap_inner
Exception in thread Thread-31 (task):
Traceback (most recent call last):
  File "/opt/homebrew/Cellar/python@3.10/3.10.15/Frameworks/Python.framework/Versions/3.10/lib/python3.10/threading.py", line 1016, in _bootstrap_inner
Exception in thread Thread-24 (task):
Traceback (most recent call last):
  File "/opt/homebrew/Cellar/python@3.10/3.10.15/Frameworks/Python.framework/Versions/3.10/lib/python3.10/threading.py", line 1016, in _bootstrap_inner
Exception in thread Thread-21 (task):
Traceback (most recent call last):
  File "/opt/homebrew/Cellar/python@3.10/3.10.15/Frameworks/Python.framework/Versions/3.10/lib/python3.10/threading.py", line 1016, in _bootstrap_inner
    self.run()
  File "/opt/homebrew/Cellar/python@3.10/3.10.15/Frameworks/Python.framework/Versions/3.10/lib/python3.10/threading.py", line 953, in run
    self.run()
  File "/opt/homebrew/Cellar/python@3.10/3.10.15/Frameworks/Python.framework/Versions/3.10/lib/python3.10/threading.py", line 953, in run
    self.run()
  File "/opt/homebrew/Cellar/python@3.10/3.10.15/Frameworks/Python.framework/Versions/3.10/lib/python3.10/threading.py", line 953, in run
Exception in thread Thread-18 (task):
Exception in thread Thread-45 (task):
Traceback (most recent call last):
  File "/opt/homebrew/Cellar/python@3.10/3.10.15/Frameworks/Python.framework/Versions/3.10/lib/python3.10/threading.py", line 1016, in _bootstrap_inner
Exception in thread Thread-73 (task):
Traceback (most recent call last):
  File "/opt/homebrew/Cellar/python@3.10/3.10.15/Frameworks/Python.framework/Versions/3.10/lib/python3.10/threading.py", line 1016, in _bootstrap_inner
Exception in thread Thread-35 (task):
  File "/opt/homebrew/Cellar/python@3.10/3.10.15/Frameworks/Python.framework/Versions/3.10/lib/python3.10/threading.py", line 1016, in _bootstrap_inner
Exception in thread Thread-36 (task):
Traceback (most recent call last):
  File "/opt/homebrew/Cellar/python@3.10/3.10.15/Frameworks/Python.framework/Versions/3.10/lib/python3.10/threading.py", line 1016, in _bootstrap_inner
Exception in thread Thread-55 (task):
Traceback (most recent call last):
Exception in thread Thread-53 (task):
Traceback (most recent call last):
  File "/opt/homebrew/Cellar/python@3.10/3.10.15/Frameworks/Python.framework/Versions/3.10/lib/python3.10/threading.py", line 1016, in _bootstrap_inner
    self.run()
  File "/opt/homebrew/Cellar/python@3.10/3.10.15/Frameworks/Python.framework/Versions/3.10/lib/python3.10/threading.py", line 953, in run
Exception in thread Thread-41 (task):
Traceback (most recent call last):
  File "/opt/homebrew/Cellar/python@3.10/3.10.15/Frameworks/Python.framework/Versions/3.10/lib/python3.10/threading.py", line 1016, in _bootstrap_inner
Exception in thread Thread-38 (task):
Traceback (most recent call last):
  File "/opt/homebrew/Cellar/python@3.10/3.10.15/Frameworks/Python.framework/Versions/3.10/lib/python3.10/threading.py", line 1016, in _bootstrap_inner
Exception in thread Thread-28 (task):
Traceback (most recent call last):
  File "/opt/homebrew/Cellar/python@3.10/3.10.15/Frameworks/Python.framework/Versions/3.10/lib/python3.10/threading.py", line 1016, in _bootstrap_inner
Exception in thread Thread-51 (task):
Traceback (most recent call last):
Exception in thread Thread-37 (task):
Traceback (most recent call last):
Exception in thread Thread-54 (task):
  File "/opt/homebrew/Cellar/python@3.10/3.10.15/Frameworks/Python.framework/Versions/3.10/lib/python3.10/threading.py", line 1016, in _bootstrap_inner
Exception in thread Thread-56 (task):
Traceback (most recent call last):
  File "/opt/homebrew/Cellar/python@3.10/3.10.15/Frameworks/Python.framework/Versions/3.10/lib/python3.10/threading.py", line 1016, in _bootstrap_inner
Exception in thread Thread-44 (task):
Traceback (most recent call last):
  File "/opt/homebrew/Cellar/python@3.10/3.10.15/Frameworks/Python.framework/Versions/3.10/lib/python3.10/threading.py", line 1016, in _bootstrap_inner
  File "/opt/homebrew/Cellar/python@3.10/3.10.15/Frameworks/Python.framework/Versions/3.10/lib/python3.10/threading.py", line 1016, in _bootstrap_inner
    self._target(*self._args, **self._kwargs)
  File "/Users/admin/Desktop/Github/SPDApiNetwork/tools/blacklist2/query.py", line 20, in task
    self.run()
  File "/opt/homebrew/Cellar/python@3.10/3.10.15/Frameworks/Python.framework/Versions/3.10/lib/python3.10/threading.py", line 953, in run
Exception in thread Thread-47 (task):
    self.run()
  File "/opt/homebrew/Cellar/python@3.10/3.10.15/Frameworks/Python.framework/Versions/3.10/lib/python3.10/threading.py", line 953, in run
Exception in thread Thread-34 (task):
Traceback (most recent call last):
  File "/opt/homebrew/Cellar/python@3.10/3.10.15/Frameworks/Python.framework/Versions/3.10/lib/python3.10/threading.py", line 1016, in _bootstrap_inner
    self.run()
  File "/opt/homebrew/Cellar/python@3.10/3.10.15/Frameworks/Python.framework/Versions/3.10/lib/python3.10/threading.py", line 953, in run
    self.run()
  File "/opt/homebrew/Cellar/python@3.10/3.10.15/Frameworks/Python.framework/Versions/3.10/lib/python3.10/threading.py", line 953, in run
    self._target(*self._args, **self._kwargs)
  File "/Users/admin/Desktop/Github/SPDApiNetwork/tools/blacklist2/query.py", line 20, in task
Exception in thread Thread-32 (task):
Traceback (most recent call last):
  File "/opt/homebrew/Cellar/python@3.10/3.10.15/Frameworks/Python.framework/Versions/3.10/lib/python3.10/threading.py", line 1016, in _bootstrap_inner
Exception in thread Thread-48 (task):
Traceback (most recent call last):
    self._target(*self._args, **self._kwargs)
  File "/Users/admin/Desktop/Github/SPDApiNetwork/tools/blacklist2/query.py", line 20, in task
    self.run()
    conn = self.postgresql_handler.pool.getconn()
  File "/opt/homebrew/lib/python3.10/site-packages/psycopg2/pool.py", line 169, in getconn
Exception in thread Thread-52 (task):
Traceback (most recent call last):
  File "/opt/homebrew/Cellar/python@3.10/3.10.15/Frameworks/Python.framework/Versions/3.10/lib/python3.10/threading.py", line 1016, in _bootstrap_inner
  File "/opt/homebrew/Cellar/python@3.10/3.10.15/Frameworks/Python.framework/Versions/3.10/lib/python3.10/threading.py", line 1016, in _bootstrap_inner
  File "/opt/homebrew/Cellar/python@3.10/3.10.15/Frameworks/Python.framework/Versions/3.10/lib/python3.10/threading.py", line 1016, in _bootstrap_inner
Exception in thread Thread-17 (task):
Exception in thread Thread-23 (task):
Traceback (most recent call last):
  File "/opt/homebrew/Cellar/python@3.10/3.10.15/Frameworks/Python.framework/Versions/3.10/lib/python3.10/threading.py", line 1016, in _bootstrap_inner
Exception in thread Thread-19 (task):
Traceback (most recent call last):
  File "/opt/homebrew/Cellar/python@3.10/3.10.15/Frameworks/Python.framework/Versions/3.10/lib/python3.10/threading.py", line 1016, in _bootstrap_inner
    self._target(*self._args, **self._kwargs)
  File "/Users/admin/Desktop/Github/SPDApiNetwork/tools/blacklist2/query.py", line 20, in task
Exception in thread Thread-29 (task):
Traceback (most recent call last):
  File "/opt/homebrew/Cellar/python@3.10/3.10.15/Frameworks/Python.framework/Versions/3.10/lib/python3.10/threading.py", line 1016, in _bootstrap_inner
    self.run()
  File "/opt/homebrew/Cellar/python@3.10/3.10.15/Frameworks/Python.framework/Versions/3.10/lib/python3.10/threading.py", line 953, in run
Traceback (most recent call last):
  File "/opt/homebrew/Cellar/python@3.10/3.10.15/Frameworks/Python.framework/Versions/3.10/lib/python3.10/threading.py", line 1016, in _bootstrap_inner
    self.run()
    self.run()
  File "/opt/homebrew/Cellar/python@3.10/3.10.15/Frameworks/Python.framework/Versions/3.10/lib/python3.10/threading.py", line 953, in run
    self.run()
  File "/opt/homebrew/Cellar/python@3.10/3.10.15/Frameworks/Python.framework/Versions/3.10/lib/python3.10/threading.py", line 953, in run
    self.run()
  File "/opt/homebrew/Cellar/python@3.10/3.10.15/Frameworks/Python.framework/Versions/3.10/lib/python3.10/threading.py", line 953, in run
    self._target(*self._args, **self._kwargs)
    self.run()
  File "/opt/homebrew/Cellar/python@3.10/3.10.15/Frameworks/Python.framework/Versions/3.10/lib/python3.10/threading.py", line 953, in run
    self.run()
  File "/opt/homebrew/Cellar/python@3.10/3.10.15/Frameworks/Python.framework/Versions/3.10/lib/python3.10/threading.py", line 953, in run
  File "/opt/homebrew/Cellar/python@3.10/3.10.15/Frameworks/Python.framework/Versions/3.10/lib/python3.10/threading.py", line 1016, in _bootstrap_inner
    self.run()
  File "/opt/homebrew/Cellar/python@3.10/3.10.15/Frameworks/Python.framework/Versions/3.10/lib/python3.10/threading.py", line 953, in run
    self.run()
  File "/opt/homebrew/Cellar/python@3.10/3.10.15/Frameworks/Python.framework/Versions/3.10/lib/python3.10/threading.py", line 953, in run
    self._target(*self._args, **self._kwargs)
  File "/Users/admin/Desktop/Github/SPDApiNetwork/tools/blacklist2/query.py", line 20, in task
  File "/opt/homebrew/Cellar/python@3.10/3.10.15/Frameworks/Python.framework/Versions/3.10/lib/python3.10/threading.py", line 1016, in _bootstrap_inner
Exception in thread Thread-42 (task):
    self._target(*self._args, **self._kwargs)
  File "/Users/admin/Desktop/Github/SPDApiNetwork/tools/blacklist2/query.py", line 20, in task
Exception in thread Thread-40 (task):
Traceback (most recent call last):
  File "/opt/homebrew/Cellar/python@3.10/3.10.15/Frameworks/Python.framework/Versions/3.10/lib/python3.10/threading.py", line 1016, in _bootstrap_inner
    self.run()
  File "/opt/homebrew/Cellar/python@3.10/3.10.15/Frameworks/Python.framework/Versions/3.10/lib/python3.10/threading.py", line 953, in run
Traceback (most recent call last):
Exception in thread Thread-46 (task):
Traceback (most recent call last):
  File "/opt/homebrew/Cellar/python@3.10/3.10.15/Frameworks/Python.framework/Versions/3.10/lib/python3.10/threading.py", line 1016, in _bootstrap_inner
    self._target(*self._args, **self._kwargs)
  File "/Users/admin/Desktop/Github/SPDApiNetwork/tools/blacklist2/query.py", line 20, in task
    self.run()
  File "/opt/homebrew/Cellar/python@3.10/3.10.15/Frameworks/Python.framework/Versions/3.10/lib/python3.10/threading.py", line 953, in run
    self._target(*self._args, **self._kwargs)
  File "/Users/admin/Desktop/Github/SPDApiNetwork/tools/blacklist2/query.py", line 20, in task
    self.run()
  File "/opt/homebrew/Cellar/python@3.10/3.10.15/Frameworks/Python.framework/Versions/3.10/lib/python3.10/threading.py", line 953, in run
Traceback (most recent call last):
  File "/opt/homebrew/Cellar/python@3.10/3.10.15/Frameworks/Python.framework/Versions/3.10/lib/python3.10/threading.py", line 1016, in _bootstrap_inner
    return self._getconn(key)
  File "/opt/homebrew/lib/python3.10/site-packages/psycopg2/pool.py", line 92, in _getconn
    self.run()
    self._target(*self._args, **self._kwargs)
  File "/Users/admin/Desktop/Github/SPDApiNetwork/tools/blacklist2/query.py", line 20, in task
    self._target(*self._args, **self._kwargs)
  File "/Users/admin/Desktop/Github/SPDApiNetwork/tools/blacklist2/query.py", line 20, in task
    self._target(*self._args, **self._kwargs)
  File "/Users/admin/Desktop/Github/SPDApiNetwork/tools/blacklist2/query.py", line 20, in task
    self.run()
    self.run()
  File "/opt/homebrew/Cellar/python@3.10/3.10.15/Frameworks/Python.framework/Versions/3.10/lib/python3.10/threading.py", line 953, in run
    self.run()
  File "/opt/homebrew/Cellar/python@3.10/3.10.15/Frameworks/Python.framework/Versions/3.10/lib/python3.10/threading.py", line 953, in run
Exception in thread Thread-49 (task):
Traceback (most recent call last):
    conn = self.postgresql_handler.pool.getconn()
  File "/opt/homebrew/lib/python3.10/site-packages/psycopg2/pool.py", line 169, in getconn
Traceback (most recent call last):
    conn = self.postgresql_handler.pool.getconn()
  File "/opt/homebrew/lib/python3.10/site-packages/psycopg2/pool.py", line 169, in getconn
    self.run()
  File "/opt/homebrew/Cellar/python@3.10/3.10.15/Frameworks/Python.framework/Versions/3.10/lib/python3.10/threading.py", line 953, in run
  File "/Users/admin/Desktop/Github/SPDApiNetwork/tools/blacklist2/query.py", line 20, in task
    raise PoolError("connection pool exhausted")
    conn = self.postgresql_handler.pool.getconn()
  File "/opt/homebrew/lib/python3.10/site-packages/psycopg2/pool.py", line 169, in getconn
  File "/opt/homebrew/Cellar/python@3.10/3.10.15/Frameworks/Python.framework/Versions/3.10/lib/python3.10/threading.py", line 1016, in _bootstrap_inner
    conn = self.postgresql_handler.pool.getconn()
  File "/opt/homebrew/lib/python3.10/site-packages/psycopg2/pool.py", line 169, in getconn
    self.run()
  File "/opt/homebrew/Cellar/python@3.10/3.10.15/Frameworks/Python.framework/Versions/3.10/lib/python3.10/threading.py", line 953, in run
    conn = self.postgresql_handler.pool.getconn()
  File "/opt/homebrew/Cellar/python@3.10/3.10.15/Frameworks/Python.framework/Versions/3.10/lib/python3.10/threading.py", line 953, in run
    self._target(*self._args, **self._kwargs)
  File "/Users/admin/Desktop/Github/SPDApiNetwork/tools/blacklist2/query.py", line 20, in task
    self._target(*self._args, **self._kwargs)
  File "/Users/admin/Desktop/Github/SPDApiNetwork/tools/blacklist2/query.py", line 20, in task
    conn = self.postgresql_handler.pool.getconn()
  File "/opt/homebrew/lib/python3.10/site-packages/psycopg2/pool.py", line 169, in getconn
    self._target(*self._args, **self._kwargs)
  File "/Users/admin/Desktop/Github/SPDApiNetwork/tools/blacklist2/query.py", line 20, in task
Exception in thread Thread-6 (task):
Traceback (most recent call last):
  File "/opt/homebrew/Cellar/python@3.10/3.10.15/Frameworks/Python.framework/Versions/3.10/lib/python3.10/threading.py", line 1016, in _bootstrap_inner
    self.run()
  File "/opt/homebrew/Cellar/python@3.10/3.10.15/Frameworks/Python.framework/Versions/3.10/lib/python3.10/threading.py", line 953, in run
    self.run()
  File "/opt/homebrew/Cellar/python@3.10/3.10.15/Frameworks/Python.framework/Versions/3.10/lib/python3.10/threading.py", line 953, in run
    self._target(*self._args, **self._kwargs)
  File "/Users/admin/Desktop/Github/SPDApiNetwork/tools/blacklist2/query.py", line 20, in task
    conn = self.postgresql_handler.pool.getconn()
    conn = self.postgresql_handler.pool.getconn()
  File "/opt/homebrew/lib/python3.10/site-packages/psycopg2/pool.py", line 169, in getconn
    conn = self.postgresql_handler.pool.getconn()
Traceback (most recent call last):
  File "/opt/homebrew/Cellar/python@3.10/3.10.15/Frameworks/Python.framework/Versions/3.10/lib/python3.10/threading.py", line 1016, in _bootstrap_inner
  File "/opt/homebrew/Cellar/python@3.10/3.10.15/Frameworks/Python.framework/Versions/3.10/lib/python3.10/threading.py", line 1016, in _bootstrap_inner
  File "/opt/homebrew/Cellar/python@3.10/3.10.15/Frameworks/Python.framework/Versions/3.10/lib/python3.10/threading.py", line 953, in run
    conn = self.postgresql_handler.pool.getconn()
    self.run()
  File "/opt/homebrew/Cellar/python@3.10/3.10.15/Frameworks/Python.framework/Versions/3.10/lib/python3.10/threading.py", line 1016, in _bootstrap_inner
    return self._getconn(key)
  File "/opt/homebrew/lib/python3.10/site-packages/psycopg2/pool.py", line 92, in _getconn
psycopg2.pool.PoolError: connection pool exhausted
    return self._getconn(key)
    conn = self.postgresql_handler.pool.getconn()
    self._target(*self._args, **self._kwargs)
    return self._getconn(key)
  File "/opt/homebrew/lib/python3.10/site-packages/psycopg2/pool.py", line 92, in _getconn
    self._target(*self._args, **self._kwargs)
  File "/Users/admin/Desktop/Github/SPDApiNetwork/tools/blacklist2/query.py", line 20, in task
    self._target(*self._args, **self._kwargs)
  File "/Users/admin/Desktop/Github/SPDApiNetwork/tools/blacklist2/query.py", line 20, in task
    self._target(*self._args, **self._kwargs)
  File "/opt/homebrew/lib/python3.10/site-packages/psycopg2/pool.py", line 169, in getconn
    self._target(*self._args, **self._kwargs)
    self._target(*self._args, **self._kwargs)
  File "/Users/admin/Desktop/Github/SPDApiNetwork/tools/blacklist2/query.py", line 20, in task
    conn = self.postgresql_handler.pool.getconn()
    self.run()
  File "/opt/homebrew/Cellar/python@3.10/3.10.15/Frameworks/Python.framework/Versions/3.10/lib/python3.10/threading.py", line 953, in run
  File "/opt/homebrew/Cellar/python@3.10/3.10.15/Frameworks/Python.framework/Versions/3.10/lib/python3.10/threading.py", line 953, in run
  File "/opt/homebrew/Cellar/python@3.10/3.10.15/Frameworks/Python.framework/Versions/3.10/lib/python3.10/threading.py", line 953, in run
    self._target(*self._args, **self._kwargs)
  File "/Users/admin/Desktop/Github/SPDApiNetwork/tools/blacklist2/query.py", line 20, in task
  File "/opt/homebrew/lib/python3.10/site-packages/psycopg2/pool.py", line 92, in _getconn
    raise PoolError("connection pool exhausted")
psycopg2.pool.PoolError: connection pool exhausted
Exception in thread Thread-57 (task):
    self.run()
  File "/opt/homebrew/Cellar/python@3.10/3.10.15/Frameworks/Python.framework/Versions/3.10/lib/python3.10/threading.py", line 953, in run
    conn = self.postgresql_handler.pool.getconn()
    return self._getconn(key)
    self.run()
    conn = self.postgresql_handler.pool.getconn()
  File "/opt/homebrew/lib/python3.10/site-packages/psycopg2/pool.py", line 169, in getconn
    self._target(*self._args, **self._kwargs)
  File "/Users/admin/Desktop/Github/SPDApiNetwork/tools/blacklist2/query.py", line 20, in task
  File "/opt/homebrew/lib/python3.10/site-packages/psycopg2/pool.py", line 169, in getconn
Traceback (most recent call last):
    conn = self.postgresql_handler.pool.getconn()
  File "/opt/homebrew/lib/python3.10/site-packages/psycopg2/pool.py", line 169, in getconn
    self.run()
Exception in thread Thread-33 (task):
    self._target(*self._args, **self._kwargs)
  File "/Users/admin/Desktop/Github/SPDApiNetwork/tools/blacklist2/query.py", line 20, in task
Exception in thread Thread-30 (task):
    self.run()
  File "/opt/homebrew/Cellar/python@3.10/3.10.15/Frameworks/Python.framework/Versions/3.10/lib/python3.10/threading.py", line 953, in run
    raise PoolError("connection pool exhausted")
  File "/opt/homebrew/lib/python3.10/site-packages/psycopg2/pool.py", line 169, in getconn
  File "/Users/admin/Desktop/Github/SPDApiNetwork/tools/blacklist2/query.py", line 20, in task
  File "/opt/homebrew/lib/python3.10/site-packages/psycopg2/pool.py", line 169, in getconn
    self._target(*self._args, **self._kwargs)
  File "/Users/admin/Desktop/Github/SPDApiNetwork/tools/blacklist2/query.py", line 20, in task
    return self._getconn(key)
  File "/opt/homebrew/lib/python3.10/site-packages/psycopg2/pool.py", line 169, in getconn
    conn = self.postgresql_handler.pool.getconn()
    conn = self.postgresql_handler.pool.getconn()
    return self._getconn(key)
    self.run()
  File "/opt/homebrew/Cellar/python@3.10/3.10.15/Frameworks/Python.framework/Versions/3.10/lib/python3.10/threading.py", line 953, in run
    self._target(*self._args, **self._kwargs)
  File "/Users/admin/Desktop/Github/SPDApiNetwork/tools/blacklist2/query.py", line 20, in task
    raise PoolError("connection pool exhausted")
  File "/Users/admin/Desktop/Github/SPDApiNetwork/tools/blacklist2/query.py", line 20, in task
Traceback (most recent call last):
  File "/opt/homebrew/Cellar/python@3.10/3.10.15/Frameworks/Python.framework/Versions/3.10/lib/python3.10/threading.py", line 1016, in _bootstrap_inner
    conn = self.postgresql_handler.pool.getconn()
  File "/opt/homebrew/lib/python3.10/site-packages/psycopg2/pool.py", line 169, in getconn
  File "/opt/homebrew/lib/python3.10/site-packages/psycopg2/pool.py", line 92, in _getconn
  File "/opt/homebrew/Cellar/python@3.10/3.10.15/Frameworks/Python.framework/Versions/3.10/lib/python3.10/threading.py", line 953, in run
    return self._getconn(key)
  File "/opt/homebrew/lib/python3.10/site-packages/psycopg2/pool.py", line 92, in _getconn
    self.run()
  File "/opt/homebrew/Cellar/python@3.10/3.10.15/Frameworks/Python.framework/Versions/3.10/lib/python3.10/threading.py", line 953, in run
    return self._getconn(key)
  File "/opt/homebrew/lib/python3.10/site-packages/psycopg2/pool.py", line 169, in getconn
  File "/opt/homebrew/lib/python3.10/site-packages/psycopg2/pool.py", line 169, in getconn
    self._target(*self._args, **self._kwargs)
  File "/Users/admin/Desktop/Github/SPDApiNetwork/tools/blacklist2/query.py", line 20, in task
    return self._getconn(key)
  File "/opt/homebrew/lib/python3.10/site-packages/psycopg2/pool.py", line 92, in _getconn
    self._target(*self._args, **self._kwargs)
  File "/Users/admin/Desktop/Github/SPDApiNetwork/tools/blacklist2/query.py", line 20, in task
    conn = self.postgresql_handler.pool.getconn()
  File "/opt/homebrew/lib/python3.10/site-packages/psycopg2/pool.py", line 169, in getconn
    conn = self.postgresql_handler.pool.getconn()
  File "/opt/homebrew/lib/python3.10/site-packages/psycopg2/pool.py", line 169, in getconn
    self.run()
    self._target(*self._args, **self._kwargs)
    raise PoolError("connection pool exhausted")
psycopg2.pool.PoolError: connection pool exhausted
    self._target(*self._args, **self._kwargs)
  File "/Users/admin/Desktop/Github/SPDApiNetwork/tools/blacklist2/query.py", line 20, in task
    conn = self.postgresql_handler.pool.getconn()
  File "/opt/homebrew/lib/python3.10/site-packages/psycopg2/pool.py", line 169, in getconn
    return self._getconn(key)
  File "/opt/homebrew/lib/python3.10/site-packages/psycopg2/pool.py", line 92, in _getconn
  File "/opt/homebrew/Cellar/python@3.10/3.10.15/Frameworks/Python.framework/Versions/3.10/lib/python3.10/threading.py", line 953, in run
    self._target(*self._args, **self._kwargs)
  File "/Users/admin/Desktop/Github/SPDApiNetwork/tools/blacklist2/query.py", line 20, in task
  File "/opt/homebrew/lib/python3.10/site-packages/psycopg2/pool.py", line 169, in getconn
psycopg2.pool.PoolError: connection pool exhausted
Traceback (most recent call last):
  File "/opt/homebrew/Cellar/python@3.10/3.10.15/Frameworks/Python.framework/Versions/3.10/lib/python3.10/threading.py", line 1016, in _bootstrap_inner
    conn = self.postgresql_handler.pool.getconn()
  File "/opt/homebrew/lib/python3.10/site-packages/psycopg2/pool.py", line 169, in getconn
  File "/opt/homebrew/Cellar/python@3.10/3.10.15/Frameworks/Python.framework/Versions/3.10/lib/python3.10/threading.py", line 953, in run
    return self._getconn(key)
  File "/opt/homebrew/lib/python3.10/site-packages/psycopg2/pool.py", line 92, in _getconn
    return self._getconn(key)
  File "/opt/homebrew/lib/python3.10/site-packages/psycopg2/pool.py", line 92, in _getconn
  File "/opt/homebrew/lib/python3.10/site-packages/psycopg2/pool.py", line 92, in _getconn
    return self._getconn(key)
    return self._getconn(key)
  File "/opt/homebrew/lib/python3.10/site-packages/psycopg2/pool.py", line 92, in _getconn
    return self._getconn(key)
  File "/opt/homebrew/lib/python3.10/site-packages/psycopg2/pool.py", line 92, in _getconn
    self._target(*self._args, **self._kwargs)
    conn = self.postgresql_handler.pool.getconn()
  File "/opt/homebrew/lib/python3.10/site-packages/psycopg2/pool.py", line 169, in getconn
    conn = self.postgresql_handler.pool.getconn()
psycopg2.pool.PoolError: connection pool exhausted
    self.run()
  File "/opt/homebrew/Cellar/python@3.10/3.10.15/Frameworks/Python.framework/Versions/3.10/lib/python3.10/threading.py", line 953, in run
    return self._getconn(key)
    return self._getconn(key)
  File "/opt/homebrew/lib/python3.10/site-packages/psycopg2/pool.py", line 92, in _getconn
    raise PoolError("connection pool exhausted")
  File "/opt/homebrew/Cellar/python@3.10/3.10.15/Frameworks/Python.framework/Versions/3.10/lib/python3.10/threading.py", line 1016, in _bootstrap_inner
    conn = self.postgresql_handler.pool.getconn()
    self._target(*self._args, **self._kwargs)
  File "/Users/admin/Desktop/Github/SPDApiNetwork/tools/blacklist2/query.py", line 20, in task
    raise PoolError("connection pool exhausted")
    conn = self.postgresql_handler.pool.getconn()
  File "/opt/homebrew/lib/python3.10/site-packages/psycopg2/pool.py", line 169, in getconn
    raise PoolError("connection pool exhausted")
    return self._getconn(key)
    self.run()
  File "/opt/homebrew/Cellar/python@3.10/3.10.15/Frameworks/Python.framework/Versions/3.10/lib/python3.10/threading.py", line 953, in run
    return self._getconn(key)
  File "/opt/homebrew/lib/python3.10/site-packages/psycopg2/pool.py", line 92, in _getconn
  File "/Users/admin/Desktop/Github/SPDApiNetwork/tools/blacklist2/query.py", line 20, in task
  File "/opt/homebrew/lib/python3.10/site-packages/psycopg2/pool.py", line 92, in _getconn
    raise PoolError("connection pool exhausted")
    self._target(*self._args, **self._kwargs)
    self._target(*self._args, **self._kwargs)
  File "/Users/admin/Desktop/Github/SPDApiNetwork/tools/blacklist2/query.py", line 20, in task
  File "/opt/homebrew/lib/python3.10/site-packages/psycopg2/pool.py", line 92, in _getconn
    raise PoolError("connection pool exhausted")
Traceback (most recent call last):
  File "/opt/homebrew/Cellar/python@3.10/3.10.15/Frameworks/Python.framework/Versions/3.10/lib/python3.10/threading.py", line 1016, in _bootstrap_inner
    raise PoolError("connection pool exhausted")
    conn = self.postgresql_handler.pool.getconn()
    conn = self.postgresql_handler.pool.getconn()
  File "/opt/homebrew/lib/python3.10/site-packages/psycopg2/pool.py", line 169, in getconn
    raise PoolError("connection pool exhausted")
psycopg2.pool.PoolError: connection pool exhausted
  File "/opt/homebrew/lib/python3.10/site-packages/psycopg2/pool.py", line 169, in getconn
    return self._getconn(key)
    self._target(*self._args, **self._kwargs)
  File "/Users/admin/Desktop/Github/SPDApiNetwork/tools/blacklist2/query.py", line 20, in task
    conn = self.postgresql_handler.pool.getconn()
  File "/opt/homebrew/lib/python3.10/site-packages/psycopg2/pool.py", line 169, in getconn
    self._target(*self._args, **self._kwargs)
    raise PoolError("connection pool exhausted")
  File "/opt/homebrew/lib/python3.10/site-packages/psycopg2/pool.py", line 169, in getconn
    self.run()
  File "/opt/homebrew/Cellar/python@3.10/3.10.15/Frameworks/Python.framework/Versions/3.10/lib/python3.10/threading.py", line 953, in run
psycopg2.pool.PoolError: connection pool exhausted
    raise PoolError("connection pool exhausted")
psycopg2.pool.PoolError: connection pool exhausted
  File "/opt/homebrew/lib/python3.10/site-packages/psycopg2/pool.py", line 92, in _getconn
  File "/opt/homebrew/lib/python3.10/site-packages/psycopg2/pool.py", line 169, in getconn
    return self._getconn(key)
  File "/opt/homebrew/lib/python3.10/site-packages/psycopg2/pool.py", line 92, in _getconn
    return self._getconn(key)
    raise PoolError("connection pool exhausted")
psycopg2.pool.PoolError: connection pool exhausted
    raise PoolError("connection pool exhausted")
  File "/Users/admin/Desktop/Github/SPDApiNetwork/tools/blacklist2/query.py", line 20, in task
psycopg2.pool.PoolError: connection pool exhausted
    conn = self.postgresql_handler.pool.getconn()
  File "/opt/homebrew/lib/python3.10/site-packages/psycopg2/pool.py", line 169, in getconn
  File "/opt/homebrew/lib/python3.10/site-packages/psycopg2/pool.py", line 169, in getconn
  File "/Users/admin/Desktop/Github/SPDApiNetwork/tools/blacklist2/query.py", line 20, in task
psycopg2.pool.PoolError: connection pool exhausted
    return self._getconn(key)
  File "/opt/homebrew/lib/python3.10/site-packages/psycopg2/pool.py", line 92, in _getconn
    conn = self.postgresql_handler.pool.getconn()
  File "/opt/homebrew/lib/python3.10/site-packages/psycopg2/pool.py", line 92, in _getconn
    raise PoolError("connection pool exhausted")
psycopg2.pool.PoolError: connection pool exhausted
psycopg2.pool.PoolError: connection pool exhausted
psycopg2.pool.PoolError: connection pool exhausted
    conn = self.postgresql_handler.pool.getconn()
  File "/opt/homebrew/lib/python3.10/site-packages/psycopg2/pool.py", line 169, in getconn
    self.run()
  File "/opt/homebrew/Cellar/python@3.10/3.10.15/Frameworks/Python.framework/Versions/3.10/lib/python3.10/threading.py", line 953, in run
  File "/opt/homebrew/lib/python3.10/site-packages/psycopg2/pool.py", line 92, in _getconn
    raise PoolError("connection pool exhausted")
    raise PoolError("connection pool exhausted")
psycopg2.pool.PoolError: connection pool exhausted
    return self._getconn(key)
  File "/opt/homebrew/lib/python3.10/site-packages/psycopg2/pool.py", line 92, in _getconn
  File "/Users/admin/Desktop/Github/SPDApiNetwork/tools/blacklist2/query.py", line 20, in task
    return self._getconn(key)
  File "/opt/homebrew/lib/python3.10/site-packages/psycopg2/pool.py", line 92, in _getconn
    self._target(*self._args, **self._kwargs)
  File "/Users/admin/Desktop/Github/SPDApiNetwork/tools/blacklist2/query.py", line 20, in task
    return self._getconn(key)
  File "/opt/homebrew/lib/python3.10/site-packages/psycopg2/pool.py", line 92, in _getconn
    return self._getconn(key)
  File "/opt/homebrew/lib/python3.10/site-packages/psycopg2/pool.py", line 92, in _getconn
psycopg2.pool.PoolError: connection pool exhausted
    return self._getconn(key)
  File "/opt/homebrew/lib/python3.10/site-packages/psycopg2/pool.py", line 92, in _getconn
    conn = self.postgresql_handler.pool.getconn()
  File "/opt/homebrew/lib/python3.10/site-packages/psycopg2/pool.py", line 169, in getconn
psycopg2.pool.PoolError: connection pool exhausted
    raise PoolError("connection pool exhausted")
    conn = self.postgresql_handler.pool.getconn()
  File "/opt/homebrew/lib/python3.10/site-packages/psycopg2/pool.py", line 169, in getconn
  File "/opt/homebrew/Cellar/python@3.10/3.10.15/Frameworks/Python.framework/Versions/3.10/lib/python3.10/threading.py", line 953, in run
  File "/Users/admin/Desktop/Github/SPDApiNetwork/tools/blacklist2/query.py", line 20, in task
    return self._getconn(key)
  File "/opt/homebrew/lib/python3.10/site-packages/psycopg2/pool.py", line 92, in _getconn
  File "/opt/homebrew/lib/python3.10/site-packages/psycopg2/pool.py", line 169, in getconn
  File "/opt/homebrew/lib/python3.10/site-packages/psycopg2/pool.py", line 92, in _getconn
    raise PoolError("connection pool exhausted")
    raise PoolError("connection pool exhausted")
psycopg2.pool.PoolError: connection pool exhausted
    self._target(*self._args, **self._kwargs)
  File "/Users/admin/Desktop/Github/SPDApiNetwork/tools/blacklist2/query.py", line 20, in task
    return self._getconn(key)
  File "/opt/homebrew/lib/python3.10/site-packages/psycopg2/pool.py", line 92, in _getconn
    raise PoolError("connection pool exhausted")
psycopg2.pool.PoolError: connection pool exhausted
    return self._getconn(key)
  File "/opt/homebrew/lib/python3.10/site-packages/psycopg2/pool.py", line 92, in _getconn
    return self._getconn(key)
  File "/opt/homebrew/lib/python3.10/site-packages/psycopg2/pool.py", line 92, in _getconn
psycopg2.pool.PoolError: connection pool exhausted
    return self._getconn(key)
    conn = self.postgresql_handler.pool.getconn()
  File "/opt/homebrew/lib/python3.10/site-packages/psycopg2/pool.py", line 169, in getconn
    raise PoolError("connection pool exhausted")
    raise PoolError("connection pool exhausted")
    return self._getconn(key)
psycopg2.pool.PoolError: connection pool exhausted
    conn = self.postgresql_handler.pool.getconn()
    raise PoolError("connection pool exhausted")
psycopg2.pool.PoolError: connection pool exhausted
    conn = self.postgresql_handler.pool.getconn()
  File "/opt/homebrew/lib/python3.10/site-packages/psycopg2/pool.py", line 169, in getconn
    conn = self.postgresql_handler.pool.getconn()
    conn = self.postgresql_handler.pool.getconn()
  File "/opt/homebrew/lib/python3.10/site-packages/psycopg2/pool.py", line 169, in getconn
  File "/opt/homebrew/lib/python3.10/site-packages/psycopg2/pool.py", line 92, in _getconn
psycopg2.pool.PoolError: connection pool exhausted
  File "/opt/homebrew/lib/python3.10/site-packages/psycopg2/pool.py", line 169, in getconn
    self._target(*self._args, **self._kwargs)
  File "/Users/admin/Desktop/Github/SPDApiNetwork/tools/blacklist2/query.py", line 20, in task
    raise PoolError("connection pool exhausted")
psycopg2.pool.PoolError: connection pool exhausted
psycopg2.pool.PoolError: connection pool exhausted
    return self._getconn(key)
    raise PoolError("connection pool exhausted")
psycopg2.pool.PoolError: connection pool exhausted
  File "/opt/homebrew/lib/python3.10/site-packages/psycopg2/pool.py", line 92, in _getconn
    raise PoolError("connection pool exhausted")
psycopg2.pool.PoolError: connection pool exhausted
    conn = self.postgresql_handler.pool.getconn()
  File "/opt/homebrew/lib/python3.10/site-packages/psycopg2/pool.py", line 169, in getconn
    raise PoolError("connection pool exhausted")
psycopg2.pool.PoolError: connection pool exhausted
    raise PoolError("connection pool exhausted")
psycopg2.pool.PoolError: connection pool exhausted
    return self._getconn(key)
  File "/opt/homebrew/lib/python3.10/site-packages/psycopg2/pool.py", line 92, in _getconn
  File "/opt/homebrew/lib/python3.10/site-packages/psycopg2/pool.py", line 92, in _getconn
    self._target(*self._args, **self._kwargs)
  File "/Users/admin/Desktop/Github/SPDApiNetwork/tools/blacklist2/query.py", line 20, in task
    return self._getconn(key)
  File "/opt/homebrew/lib/python3.10/site-packages/psycopg2/pool.py", line 92, in _getconn
    return self._getconn(key)
  File "/opt/homebrew/lib/python3.10/site-packages/psycopg2/pool.py", line 92, in _getconn
    raise PoolError("connection pool exhausted")
psycopg2.pool.PoolError: connection pool exhausted
  File "/opt/homebrew/lib/python3.10/site-packages/psycopg2/pool.py", line 169, in getconn
psycopg2.pool.PoolError: connection pool exhausted
    conn = self.postgresql_handler.pool.getconn()
  File "/opt/homebrew/lib/python3.10/site-packages/psycopg2/pool.py", line 169, in getconn
    raise PoolError("connection pool exhausted")
psycopg2.pool.PoolError: connection pool exhausted
    raise PoolError("connection pool exhausted")
psycopg2.pool.PoolError: connection pool exhausted
    raise PoolError("connection pool exhausted")
    return self._getconn(key)
  File "/opt/homebrew/lib/python3.10/site-packages/psycopg2/pool.py", line 92, in _getconn
    return self._getconn(key)
    raise PoolError("connection pool exhausted")
    return self._getconn(key)
  File "/opt/homebrew/lib/python3.10/site-packages/psycopg2/pool.py", line 92, in _getconn
psycopg2.pool.PoolError: connection pool exhausted
    raise PoolError("connection pool exhausted")
psycopg2.pool.PoolError: connection pool exhausted
    raise PoolError("connection pool exhausted")
  File "/opt/homebrew/lib/python3.10/site-packages/psycopg2/pool.py", line 92, in _getconn
    raise PoolError("connection pool exhausted")
psycopg2.pool.PoolError: connection pool exhausted
psycopg2.pool.PoolError: connection pool exhausted
  File "/opt/homebrew/lib/python3.10/site-packages/psycopg2/pool.py", line 92, in _getconn
    raise PoolError("connection pool exhausted")
psycopg2.pool.PoolError: connection pool exhausted
    raise PoolError("connection pool exhausted")
psycopg2.pool.PoolError: connection pool exhausted
    raise PoolError("connection pool exhausted")
psycopg2.pool.PoolError: connection pool exhausted
psycopg2.pool.PoolError: connection pool exhausted
psycopg2.pool.PoolError: connection pool exhausted
Exception in thread Thread-15 (task):
Traceback (most recent call last):
  File "/opt/homebrew/Cellar/python@3.10/3.10.15/Frameworks/Python.framework/Versions/3.10/lib/python3.10/threading.py", line 1016, in _bootstrap_inner
    self.run()
  File "/opt/homebrew/Cellar/python@3.10/3.10.15/Frameworks/Python.framework/Versions/3.10/lib/python3.10/threading.py", line 953, in run
    self._target(*self._args, **self._kwargs)
  File "/Users/admin/Desktop/Github/SPDApiNetwork/tools/blacklist2/query.py", line 22, in task
    cursor.execute(
psycopg2.errors.UndefinedTable: relation "blacklisted_ips" does not exist
LINE 1: SELECT * FROM blacklisted_ips WHERE ip = '37.123.97.23' AND ...
                      ^

Exception in thread Thread-58 (task):
Traceback (most recent call last):
  File "/opt/homebrew/Cellar/python@3.10/3.10.15/Frameworks/Python.framework/Versions/3.10/lib/python3.10/threading.py", line 1016, in _bootstrap_inner
Exception in thread Thread-80 (task):
Traceback (most recent call last):
Exception in thread Thread-60 (task):
Traceback (most recent call last):
  File "/opt/homebrew/Cellar/python@3.10/3.10.15/Frameworks/Python.framework/Versions/3.10/lib/python3.10/threading.py", line 1016, in _bootstrap_inner
  File "/opt/homebrew/Cellar/python@3.10/3.10.15/Frameworks/Python.framework/Versions/3.10/lib/python3.10/threading.py", line 1016, in _bootstrap_inner
    self.run()
  File "/opt/homebrew/Cellar/python@3.10/3.10.15/Frameworks/Python.framework/Versions/3.10/lib/python3.10/threading.py", line 953, in run
    self.run()
  File "/opt/homebrew/Cellar/python@3.10/3.10.15/Frameworks/Python.framework/Versions/3.10/lib/python3.10/threading.py", line 953, in run
    self.run()
  File "/opt/homebrew/Cellar/python@3.10/3.10.15/Frameworks/Python.framework/Versions/3.10/lib/python3.10/threading.py", line 953, in run
    self._target(*self._args, **self._kwargs)
  File "/Users/admin/Desktop/Github/SPDApiNetwork/tools/blacklist2/query.py", line 20, in task
    self._target(*self._args, **self._kwargs)
  File "/Users/admin/Desktop/Github/SPDApiNetwork/tools/blacklist2/query.py", line 20, in task
    self._target(*self._args, **self._kwargs)
  File "/Users/admin/Desktop/Github/SPDApiNetwork/tools/blacklist2/query.py", line 20, in task
    conn = self.postgresql_handler.pool.getconn()
  File "/opt/homebrew/lib/python3.10/site-packages/psycopg2/pool.py", line 169, in getconn
    conn = self.postgresql_handler.pool.getconn()
    conn = self.postgresql_handler.pool.getconn()
  File "/opt/homebrew/lib/python3.10/site-packages/psycopg2/pool.py", line 169, in getconn
  File "/opt/homebrew/lib/python3.10/site-packages/psycopg2/pool.py", line 169, in getconn
    return self._getconn(key)
  File "/opt/homebrew/lib/python3.10/site-packages/psycopg2/pool.py", line 92, in _getconn
    return self._getconn(key)
  File "/opt/homebrew/lib/python3.10/site-packages/psycopg2/pool.py", line 92, in _getconn
    return self._getconn(key)
  File "/opt/homebrew/lib/python3.10/site-packages/psycopg2/pool.py", line 92, in _getconn
    raise PoolError("connection pool exhausted")
psycopg2.pool.PoolError: connection pool exhausted
    raise PoolError("connection pool exhausted")
psycopg2.pool.PoolError: connection pool exhausted
    raise PoolError("connection pool exhausted")
psycopg2.pool.PoolError: connection pool exhausted
Exception in thread Thread-59 (task):
Traceback (most recent call last):
  File "/opt/homebrew/Cellar/python@3.10/3.10.15/Frameworks/Python.framework/Versions/3.10/lib/python3.10/threading.py", line 1016, in _bootstrap_inner
Exception in thread Thread-63 (task):
Traceback (most recent call last):
  File "/opt/homebrew/Cellar/python@3.10/3.10.15/Frameworks/Python.framework/Versions/3.10/lib/python3.10/threading.py", line 1016, in _bootstrap_inner
    self.run()
  File "/opt/homebrew/Cellar/python@3.10/3.10.15/Frameworks/Python.framework/Versions/3.10/lib/python3.10/threading.py", line 953, in run
    self.run()
  File "/opt/homebrew/Cellar/python@3.10/3.10.15/Frameworks/Python.framework/Versions/3.10/lib/python3.10/threading.py", line 953, in run
    self._target(*self._args, **self._kwargs)
  File "/Users/admin/Desktop/Github/SPDApiNetwork/tools/blacklist2/query.py", line 20, in task
    self._target(*self._args, **self._kwargs)
  File "/Users/admin/Desktop/Github/SPDApiNetwork/tools/blacklist2/query.py", line 20, in task
    conn = self.postgresql_handler.pool.getconn()
  File "/opt/homebrew/lib/python3.10/site-packages/psycopg2/pool.py", line 169, in getconn
    conn = self.postgresql_handler.pool.getconn()
  File "/opt/homebrew/lib/python3.10/site-packages/psycopg2/pool.py", line 169, in getconn
    return self._getconn(key)
  File "/opt/homebrew/lib/python3.10/site-packages/psycopg2/pool.py", line 92, in _getconn
    return self._getconn(key)
  File "/opt/homebrew/lib/python3.10/site-packages/psycopg2/pool.py", line 92, in _getconn
    raise PoolError("connection pool exhausted")
psycopg2.pool.PoolError: connection pool exhausted
    raise PoolError("connection pool exhausted")
psycopg2.pool.PoolError: connection pool exhausted
Exception in thread Thread-62 (task):
Traceback (most recent call last):
  File "/opt/homebrew/Cellar/python@3.10/3.10.15/Frameworks/Python.framework/Versions/3.10/lib/python3.10/threading.py", line 1016, in _bootstrap_inner
    self.run()
  File "/opt/homebrew/Cellar/python@3.10/3.10.15/Frameworks/Python.framework/Versions/3.10/lib/python3.10/threading.py", line 953, in run
    self._target(*self._args, **self._kwargs)
  File "/Users/admin/Desktop/Github/SPDApiNetwork/tools/blacklist2/query.py", line 20, in task
    conn = self.postgresql_handler.pool.getconn()
  File "/opt/homebrew/lib/python3.10/site-packages/psycopg2/pool.py", line 169, in getconn
    return self._getconn(key)
  File "/opt/homebrew/lib/python3.10/site-packages/psycopg2/pool.py", line 92, in _getconn
    raise PoolError("connection pool exhausted")
psycopg2.pool.PoolError: connection pool exhausted
Exception in thread Thread-67 (task):
Exception in thread Thread-64 (task):
Traceback (most recent call last):
Exception in thread Thread-66 (task):
Traceback (most recent call last):
  File "/opt/homebrew/Cellar/python@3.10/3.10.15/Frameworks/Python.framework/Versions/3.10/lib/python3.10/threading.py", line 1016, in _bootstrap_inner
Traceback (most recent call last):
  File "/opt/homebrew/Cellar/python@3.10/3.10.15/Frameworks/Python.framework/Versions/3.10/lib/python3.10/threading.py", line 1016, in _bootstrap_inner
Exception in thread Thread-68 (task):
Traceback (most recent call last):
  File "/opt/homebrew/Cellar/python@3.10/3.10.15/Frameworks/Python.framework/Versions/3.10/lib/python3.10/threading.py", line 1016, in _bootstrap_inner
  File "/opt/homebrew/Cellar/python@3.10/3.10.15/Frameworks/Python.framework/Versions/3.10/lib/python3.10/threading.py", line 1016, in _bootstrap_inner
Exception in thread Thread-65 (task):
Traceback (most recent call last):
  File "/opt/homebrew/Cellar/python@3.10/3.10.15/Frameworks/Python.framework/Versions/3.10/lib/python3.10/threading.py", line 1016, in _bootstrap_inner
    self.run()
  File "/opt/homebrew/Cellar/python@3.10/3.10.15/Frameworks/Python.framework/Versions/3.10/lib/python3.10/threading.py", line 953, in run
    self.run()
  File "/opt/homebrew/Cellar/python@3.10/3.10.15/Frameworks/Python.framework/Versions/3.10/lib/python3.10/threading.py", line 953, in run
    self.run()
  File "/opt/homebrew/Cellar/python@3.10/3.10.15/Frameworks/Python.framework/Versions/3.10/lib/python3.10/threading.py", line 953, in run
    self.run()
  File "/opt/homebrew/Cellar/python@3.10/3.10.15/Frameworks/Python.framework/Versions/3.10/lib/python3.10/threading.py", line 953, in run
    self._target(*self._args, **self._kwargs)
    self.run()
  File "/opt/homebrew/Cellar/python@3.10/3.10.15/Frameworks/Python.framework/Versions/3.10/lib/python3.10/threading.py", line 953, in run
    self._target(*self._args, **self._kwargs)
  File "/Users/admin/Desktop/Github/SPDApiNetwork/tools/blacklist2/query.py", line 20, in task
    self._target(*self._args, **self._kwargs)
  File "/Users/admin/Desktop/Github/SPDApiNetwork/tools/blacklist2/query.py", line 20, in task
  File "/Users/admin/Desktop/Github/SPDApiNetwork/tools/blacklist2/query.py", line 20, in task
    self._target(*self._args, **self._kwargs)
  File "/Users/admin/Desktop/Github/SPDApiNetwork/tools/blacklist2/query.py", line 20, in task
    conn = self.postgresql_handler.pool.getconn()
    self._target(*self._args, **self._kwargs)
  File "/Users/admin/Desktop/Github/SPDApiNetwork/tools/blacklist2/query.py", line 20, in task
    conn = self.postgresql_handler.pool.getconn()
  File "/opt/homebrew/lib/python3.10/site-packages/psycopg2/pool.py", line 169, in getconn
    conn = self.postgresql_handler.pool.getconn()
  File "/opt/homebrew/lib/python3.10/site-packages/psycopg2/pool.py", line 169, in getconn
    conn = self.postgresql_handler.pool.getconn()
  File "/opt/homebrew/lib/python3.10/site-packages/psycopg2/pool.py", line 169, in getconn
  File "/opt/homebrew/lib/python3.10/site-packages/psycopg2/pool.py", line 169, in getconn
    conn = self.postgresql_handler.pool.getconn()
  File "/opt/homebrew/lib/python3.10/site-packages/psycopg2/pool.py", line 169, in getconn
    return self._getconn(key)
  File "/opt/homebrew/lib/python3.10/site-packages/psycopg2/pool.py", line 92, in _getconn
    return self._getconn(key)
  File "/opt/homebrew/lib/python3.10/site-packages/psycopg2/pool.py", line 92, in _getconn
    return self._getconn(key)
  File "/opt/homebrew/lib/python3.10/site-packages/psycopg2/pool.py", line 92, in _getconn
    raise PoolError("connection pool exhausted")
    raise PoolError("connection pool exhausted")
psycopg2.pool.PoolError: connection pool exhausted
    return self._getconn(key)
    return self._getconn(key)
  File "/opt/homebrew/lib/python3.10/site-packages/psycopg2/pool.py", line 92, in _getconn
  File "/opt/homebrew/lib/python3.10/site-packages/psycopg2/pool.py", line 92, in _getconn
psycopg2.pool.PoolError: connection pool exhausted
    raise PoolError("connection pool exhausted")
psycopg2.pool.PoolError: connection pool exhausted
    raise PoolError("connection pool exhausted")
    raise PoolError("connection pool exhausted")
psycopg2.pool.PoolError: connection pool exhausted
psycopg2.pool.PoolError: connection pool exhausted
Exception in thread Thread-69 (task):
Traceback (most recent call last):
  File "/opt/homebrew/Cellar/python@3.10/3.10.15/Frameworks/Python.framework/Versions/3.10/lib/python3.10/threading.py", line 1016, in _bootstrap_inner
    self.run()
  File "/opt/homebrew/Cellar/python@3.10/3.10.15/Frameworks/Python.framework/Versions/3.10/lib/python3.10/threading.py", line 953, in run
    self._target(*self._args, **self._kwargs)
  File "/Users/admin/Desktop/Github/SPDApiNetwork/tools/blacklist2/query.py", line 20, in task
    conn = self.postgresql_handler.pool.getconn()
  File "/opt/homebrew/lib/python3.10/site-packages/psycopg2/pool.py", line 169, in getconn
    return self._getconn(key)
  File "/opt/homebrew/lib/python3.10/site-packages/psycopg2/pool.py", line 92, in _getconn
    raise PoolError("connection pool exhausted")
psycopg2.pool.PoolError: connection pool exhausted
Exception in thread Thread-39 (task):
Traceback (most recent call last):
  File "/opt/homebrew/Cellar/python@3.10/3.10.15/Frameworks/Python.framework/Versions/3.10/lib/python3.10/threading.py", line 1016, in _bootstrap_inner
    self.run()
  File "/opt/homebrew/Cellar/python@3.10/3.10.15/Frameworks/Python.framework/Versions/3.10/lib/python3.10/threading.py", line 953, in run
    self._target(*self._args, **self._kwargs)
  File "/Users/admin/Desktop/Github/SPDApiNetwork/tools/blacklist2/query.py", line 20, in task
    conn = self.postgresql_handler.pool.getconn()
  File "/opt/homebrew/lib/python3.10/site-packages/psycopg2/pool.py", line 169, in getconn
    return self._getconn(key)
  File "/opt/homebrew/lib/python3.10/site-packages/psycopg2/pool.py", line 92, in _getconn
    raise PoolError("connection pool exhausted")
psycopg2.pool.PoolError: connection pool exhausted
Exception in thread Thread-72 (task):
Traceback (most recent call last):
  File "/opt/homebrew/Cellar/python@3.10/3.10.15/Frameworks/Python.framework/Versions/3.10/lib/python3.10/threading.py", line 1016, in _bootstrap_inner
Exception in thread Thread-85 (task):
Traceback (most recent call last):
  File "/opt/homebrew/Cellar/python@3.10/3.10.15/Frameworks/Python.framework/Versions/3.10/lib/python3.10/threading.py", line 1016, in _bootstrap_inner
    self.run()
Exception in thread Thread-50 (task):
Traceback (most recent call last):
  File "/opt/homebrew/Cellar/python@3.10/3.10.15/Frameworks/Python.framework/Versions/3.10/lib/python3.10/threading.py", line 1016, in _bootstrap_inner
    self.run()
  File "/opt/homebrew/Cellar/python@3.10/3.10.15/Frameworks/Python.framework/Versions/3.10/lib/python3.10/threading.py", line 953, in run
Exception in thread Thread-75 (task):
Traceback (most recent call last):
  File "/opt/homebrew/Cellar/python@3.10/3.10.15/Frameworks/Python.framework/Versions/3.10/lib/python3.10/threading.py", line 953, in run
    self._target(*self._args, **self._kwargs)
  File "/Users/admin/Desktop/Github/SPDApiNetwork/tools/blacklist2/query.py", line 20, in task
  File "/opt/homebrew/Cellar/python@3.10/3.10.15/Frameworks/Python.framework/Versions/3.10/lib/python3.10/threading.py", line 1016, in _bootstrap_inner
    self.run()
  File "/opt/homebrew/Cellar/python@3.10/3.10.15/Frameworks/Python.framework/Versions/3.10/lib/python3.10/threading.py", line 953, in run
Exception in thread Thread-74 (task):
Traceback (most recent call last):
  File "/opt/homebrew/Cellar/python@3.10/3.10.15/Frameworks/Python.framework/Versions/3.10/lib/python3.10/threading.py", line 1016, in _bootstrap_inner
    conn = self.postgresql_handler.pool.getconn()
  File "/opt/homebrew/lib/python3.10/site-packages/psycopg2/pool.py", line 169, in getconn
    self._target(*self._args, **self._kwargs)
  File "/Users/admin/Desktop/Github/SPDApiNetwork/tools/blacklist2/query.py", line 20, in task
    self.run()
  File "/opt/homebrew/Cellar/python@3.10/3.10.15/Frameworks/Python.framework/Versions/3.10/lib/python3.10/threading.py", line 953, in run
    self._target(*self._args, **self._kwargs)
  File "/Users/admin/Desktop/Github/SPDApiNetwork/tools/blacklist2/query.py", line 20, in task
    self.run()
  File "/opt/homebrew/Cellar/python@3.10/3.10.15/Frameworks/Python.framework/Versions/3.10/lib/python3.10/threading.py", line 953, in run
    conn = self.postgresql_handler.pool.getconn()
  File "/opt/homebrew/lib/python3.10/site-packages/psycopg2/pool.py", line 169, in getconn
    return self._getconn(key)
  File "/opt/homebrew/lib/python3.10/site-packages/psycopg2/pool.py", line 92, in _getconn
    self._target(*self._args, **self._kwargs)
  File "/Users/admin/Desktop/Github/SPDApiNetwork/tools/blacklist2/query.py", line 20, in task
    raise PoolError("connection pool exhausted")
    return self._getconn(key)
  File "/opt/homebrew/lib/python3.10/site-packages/psycopg2/pool.py", line 92, in _getconn
psycopg2.pool.PoolError: connection pool exhausted
    self._target(*self._args, **self._kwargs)
  File "/Users/admin/Desktop/Github/SPDApiNetwork/tools/blacklist2/query.py", line 20, in task
    conn = self.postgresql_handler.pool.getconn()
  File "/opt/homebrew/lib/python3.10/site-packages/psycopg2/pool.py", line 169, in getconn
    conn = self.postgresql_handler.pool.getconn()
  File "/opt/homebrew/lib/python3.10/site-packages/psycopg2/pool.py", line 169, in getconn
    raise PoolError("connection pool exhausted")
psycopg2.pool.PoolError: connection pool exhausted
    conn = self.postgresql_handler.pool.getconn()
  File "/opt/homebrew/lib/python3.10/site-packages/psycopg2/pool.py", line 169, in getconn
    return self._getconn(key)
  File "/opt/homebrew/lib/python3.10/site-packages/psycopg2/pool.py", line 92, in _getconn
    return self._getconn(key)
  File "/opt/homebrew/lib/python3.10/site-packages/psycopg2/pool.py", line 92, in _getconn
    return self._getconn(key)
  File "/opt/homebrew/lib/python3.10/site-packages/psycopg2/pool.py", line 92, in _getconn
    raise PoolError("connection pool exhausted")
    raise PoolError("connection pool exhausted")
psycopg2.pool.PoolError: connection pool exhausted
psycopg2.pool.PoolError: connection pool exhausted
    raise PoolError("connection pool exhausted")
psycopg2.pool.PoolError: connection pool exhausted
Exception in thread Thread-76 (task):
Traceback (most recent call last):
  File "/opt/homebrew/Cellar/python@3.10/3.10.15/Frameworks/Python.framework/Versions/3.10/lib/python3.10/threading.py", line 1016, in _bootstrap_inner
    self.run()
  File "/opt/homebrew/Cellar/python@3.10/3.10.15/Frameworks/Python.framework/Versions/3.10/lib/python3.10/threading.py", line 953, in run
    self._target(*self._args, **self._kwargs)
  File "/Users/admin/Desktop/Github/SPDApiNetwork/tools/blacklist2/query.py", line 20, in task
    conn = self.postgresql_handler.pool.getconn()
  File "/opt/homebrew/lib/python3.10/site-packages/psycopg2/pool.py", line 169, in getconn
    return self._getconn(key)
  File "/opt/homebrew/lib/python3.10/site-packages/psycopg2/pool.py", line 92, in _getconn
    raise PoolError("connection pool exhausted")
psycopg2.pool.PoolError: connection pool exhausted
Exception in thread Thread-43 (task):
Traceback (most recent call last):
  File "/opt/homebrew/Cellar/python@3.10/3.10.15/Frameworks/Python.framework/Versions/3.10/lib/python3.10/threading.py", line 1016, in _bootstrap_inner
    self.run()
  File "/opt/homebrew/Cellar/python@3.10/3.10.15/Frameworks/Python.framework/Versions/3.10/lib/python3.10/threading.py", line 953, in run
    self._target(*self._args, **self._kwargs)
  File "/Users/admin/Desktop/Github/SPDApiNetwork/tools/blacklist2/query.py", line 20, in task
    conn = self.postgresql_handler.pool.getconn()
  File "/opt/homebrew/lib/python3.10/site-packages/psycopg2/pool.py", line 169, in getconn
    return self._getconn(key)
  File "/opt/homebrew/lib/python3.10/site-packages/psycopg2/pool.py", line 92, in _getconn
    raise PoolError("connection pool exhausted")
psycopg2.pool.PoolError: connection pool exhausted
Exception in thread Thread-78 (task):
Traceback (most recent call last):
  File "/opt/homebrew/Cellar/python@3.10/3.10.15/Frameworks/Python.framework/Versions/3.10/lib/python3.10/threading.py", line 1016, in _bootstrap_inner
    self.run()
  File "/opt/homebrew/Cellar/python@3.10/3.10.15/Frameworks/Python.framework/Versions/3.10/lib/python3.10/threading.py", line 953, in run
    self._target(*self._args, **self._kwargs)
  File "/Users/admin/Desktop/Github/SPDApiNetwork/tools/blacklist2/query.py", line 20, in task
    conn = self.postgresql_handler.pool.getconn()
  File "/opt/homebrew/lib/python3.10/site-packages/psycopg2/pool.py", line 169, in getconn
    return self._getconn(key)
  File "/opt/homebrew/lib/python3.10/site-packages/psycopg2/pool.py", line 92, in _getconn
    raise PoolError("connection pool exhausted")
psycopg2.pool.PoolError: connection pool exhausted
Exception in thread Thread-81 (task):
Traceback (most recent call last):
  File "/opt/homebrew/Cellar/python@3.10/3.10.15/Frameworks/Python.framework/Versions/3.10/lib/python3.10/threading.py", line 1016, in _bootstrap_inner
Exception in thread Thread-61 (task):
Traceback (most recent call last):
  File "/opt/homebrew/Cellar/python@3.10/3.10.15/Frameworks/Python.framework/Versions/3.10/lib/python3.10/threading.py", line 1016, in _bootstrap_inner
Exception in thread Thread-83 (task):
Traceback (most recent call last):
  File "/opt/homebrew/Cellar/python@3.10/3.10.15/Frameworks/Python.framework/Versions/3.10/lib/python3.10/threading.py", line 1016, in _bootstrap_inner
Exception in thread Thread-79 (task):
Traceback (most recent call last):
  File "/opt/homebrew/Cellar/python@3.10/3.10.15/Frameworks/Python.framework/Versions/3.10/lib/python3.10/threading.py", line 1016, in _bootstrap_inner
Exception in thread Thread-82 (task):
Traceback (most recent call last):
    self.run()
  File "/opt/homebrew/Cellar/python@3.10/3.10.15/Frameworks/Python.framework/Versions/3.10/lib/python3.10/threading.py", line 953, in run
    self.run()
  File "/opt/homebrew/Cellar/python@3.10/3.10.15/Frameworks/Python.framework/Versions/3.10/lib/python3.10/threading.py", line 953, in run
  File "/opt/homebrew/Cellar/python@3.10/3.10.15/Frameworks/Python.framework/Versions/3.10/lib/python3.10/threading.py", line 1016, in _bootstrap_inner
    self.run()
  File "/opt/homebrew/Cellar/python@3.10/3.10.15/Frameworks/Python.framework/Versions/3.10/lib/python3.10/threading.py", line 953, in run
    self.run()
  File "/opt/homebrew/Cellar/python@3.10/3.10.15/Frameworks/Python.framework/Versions/3.10/lib/python3.10/threading.py", line 953, in run
    self._target(*self._args, **self._kwargs)
  File "/Users/admin/Desktop/Github/SPDApiNetwork/tools/blacklist2/query.py", line 20, in task
    self._target(*self._args, **self._kwargs)
  File "/Users/admin/Desktop/Github/SPDApiNetwork/tools/blacklist2/query.py", line 20, in task
    self.run()
  File "/opt/homebrew/Cellar/python@3.10/3.10.15/Frameworks/Python.framework/Versions/3.10/lib/python3.10/threading.py", line 953, in run
    self._target(*self._args, **self._kwargs)
  File "/Users/admin/Desktop/Github/SPDApiNetwork/tools/blacklist2/query.py", line 20, in task
    self._target(*self._args, **self._kwargs)
  File "/Users/admin/Desktop/Github/SPDApiNetwork/tools/blacklist2/query.py", line 20, in task
    conn = self.postgresql_handler.pool.getconn()
  File "/opt/homebrew/lib/python3.10/site-packages/psycopg2/pool.py", line 169, in getconn
    conn = self.postgresql_handler.pool.getconn()
  File "/opt/homebrew/lib/python3.10/site-packages/psycopg2/pool.py", line 169, in getconn
    conn = self.postgresql_handler.pool.getconn()
  File "/opt/homebrew/lib/python3.10/site-packages/psycopg2/pool.py", line 169, in getconn
    return self._getconn(key)
  File "/opt/homebrew/lib/python3.10/site-packages/psycopg2/pool.py", line 92, in _getconn
    return self._getconn(key)
  File "/opt/homebrew/lib/python3.10/site-packages/psycopg2/pool.py", line 92, in _getconn
    return self._getconn(key)
  File "/opt/homebrew/lib/python3.10/site-packages/psycopg2/pool.py", line 92, in _getconn
    raise PoolError("connection pool exhausted")
    conn = self.postgresql_handler.pool.getconn()
  File "/opt/homebrew/lib/python3.10/site-packages/psycopg2/pool.py", line 169, in getconn
    raise PoolError("connection pool exhausted")
psycopg2.pool.PoolError: connection pool exhausted
psycopg2.pool.PoolError: connection pool exhausted
    return self._getconn(key)
  File "/opt/homebrew/lib/python3.10/site-packages/psycopg2/pool.py", line 92, in _getconn
    self._target(*self._args, **self._kwargs)
  File "/Users/admin/Desktop/Github/SPDApiNetwork/tools/blacklist2/query.py", line 20, in task
    raise PoolError("connection pool exhausted")
psycopg2.pool.PoolError: connection pool exhausted
    raise PoolError("connection pool exhausted")
psycopg2.pool.PoolError: connection pool exhausted
    conn = self.postgresql_handler.pool.getconn()
  File "/opt/homebrew/lib/python3.10/site-packages/psycopg2/pool.py", line 169, in getconn
    return self._getconn(key)
  File "/opt/homebrew/lib/python3.10/site-packages/psycopg2/pool.py", line 92, in _getconn
    raise PoolError("connection pool exhausted")
psycopg2.pool.PoolError: connection pool exhausted
Exception in thread Thread-84 (task):
Traceback (most recent call last):
  File "/opt/homebrew/Cellar/python@3.10/3.10.15/Frameworks/Python.framework/Versions/3.10/lib/python3.10/threading.py", line 1016, in _bootstrap_inner
    self.run()
  File "/opt/homebrew/Cellar/python@3.10/3.10.15/Frameworks/Python.framework/Versions/3.10/lib/python3.10/threading.py", line 953, in run
    self._target(*self._args, **self._kwargs)
  File "/Users/admin/Desktop/Github/SPDApiNetwork/tools/blacklist2/query.py", line 20, in task
    conn = self.postgresql_handler.pool.getconn()
  File "/opt/homebrew/lib/python3.10/site-packages/psycopg2/pool.py", line 169, in getconn
    return self._getconn(key)
  File "/opt/homebrew/lib/python3.10/site-packages/psycopg2/pool.py", line 92, in _getconn
    raise PoolError("connection pool exhausted")
psycopg2.pool.PoolError: connection pool exhausted
Exception in thread Thread-71 (task):
Traceback (most recent call last):
  File "/opt/homebrew/Cellar/python@3.10/3.10.15/Frameworks/Python.framework/Versions/3.10/lib/python3.10/threading.py", line 1016, in _bootstrap_inner
    self.run()
  File "/opt/homebrew/Cellar/python@3.10/3.10.15/Frameworks/Python.framework/Versions/3.10/lib/python3.10/threading.py", line 953, in run
    self._target(*self._args, **self._kwargs)
  File "/Users/admin/Desktop/Github/SPDApiNetwork/tools/blacklist2/query.py", line 20, in task
    conn = self.postgresql_handler.pool.getconn()
  File "/opt/homebrew/lib/python3.10/site-packages/psycopg2/pool.py", line 169, in getconn
    return self._getconn(key)
  File "/opt/homebrew/lib/python3.10/site-packages/psycopg2/pool.py", line 92, in _getconn
    raise PoolError("connection pool exhausted")
psycopg2.pool.PoolError: connection pool exhausted
Exception in thread Thread-86 (task):
Traceback (most recent call last):
  File "/opt/homebrew/Cellar/python@3.10/3.10.15/Frameworks/Python.framework/Versions/3.10/lib/python3.10/threading.py", line 1016, in _bootstrap_inner
    self.run()
  File "/opt/homebrew/Cellar/python@3.10/3.10.15/Frameworks/Python.framework/Versions/3.10/lib/python3.10/threading.py", line 953, in run
    self._target(*self._args, **self._kwargs)
  File "/Users/admin/Desktop/Github/SPDApiNetwork/tools/blacklist2/query.py", line 20, in task
    conn = self.postgresql_handler.pool.getconn()
  File "/opt/homebrew/lib/python3.10/site-packages/psycopg2/pool.py", line 169, in getconn
    return self._getconn(key)
  File "/opt/homebrew/lib/python3.10/site-packages/psycopg2/pool.py", line 92, in _getconn
    raise PoolError("connection pool exhausted")
psycopg2.pool.PoolError: connection pool exhausted
Exception in thread Thread-87 (task):
Traceback (most recent call last):
  File "/opt/homebrew/Cellar/python@3.10/3.10.15/Frameworks/Python.framework/Versions/3.10/lib/python3.10/threading.py", line 1016, in _bootstrap_inner
    self.run()
  File "/opt/homebrew/Cellar/python@3.10/3.10.15/Frameworks/Python.framework/Versions/3.10/lib/python3.10/threading.py", line 953, in run
    self._target(*self._args, **self._kwargs)
  File "/Users/admin/Desktop/Github/SPDApiNetwork/tools/blacklist2/query.py", line 20, in task
Exception in thread Thread-88 (task):
Traceback (most recent call last):
  File "/opt/homebrew/Cellar/python@3.10/3.10.15/Frameworks/Python.framework/Versions/3.10/lib/python3.10/threading.py", line 1016, in _bootstrap_inner
    conn = self.postgresql_handler.pool.getconn()
  File "/opt/homebrew/lib/python3.10/site-packages/psycopg2/pool.py", line 169, in getconn
Exception in thread Thread-90 (task):
Traceback (most recent call last):
  File "/opt/homebrew/Cellar/python@3.10/3.10.15/Frameworks/Python.framework/Versions/3.10/lib/python3.10/threading.py", line 1016, in _bootstrap_inner
Exception in thread Thread-89 (task):
Traceback (most recent call last):
  File "/opt/homebrew/Cellar/python@3.10/3.10.15/Frameworks/Python.framework/Versions/3.10/lib/python3.10/threading.py", line 1016, in _bootstrap_inner
    return self._getconn(key)
  File "/opt/homebrew/lib/python3.10/site-packages/psycopg2/pool.py", line 92, in _getconn
    self.run()
Exception in thread Thread-91 (task):
Traceback (most recent call last):
  File "/opt/homebrew/Cellar/python@3.10/3.10.15/Frameworks/Python.framework/Versions/3.10/lib/python3.10/threading.py", line 953, in run
    raise PoolError("connection pool exhausted")
psycopg2.pool.PoolError: connection pool exhausted
  File "/opt/homebrew/Cellar/python@3.10/3.10.15/Frameworks/Python.framework/Versions/3.10/lib/python3.10/threading.py", line 1016, in _bootstrap_inner
    self.run()
  File "/opt/homebrew/Cellar/python@3.10/3.10.15/Frameworks/Python.framework/Versions/3.10/lib/python3.10/threading.py", line 953, in run
    self.run()
    self._target(*self._args, **self._kwargs)
  File "/opt/homebrew/Cellar/python@3.10/3.10.15/Frameworks/Python.framework/Versions/3.10/lib/python3.10/threading.py", line 953, in run
    self.run()
  File "/opt/homebrew/Cellar/python@3.10/3.10.15/Frameworks/Python.framework/Versions/3.10/lib/python3.10/threading.py", line 953, in run
    self._target(*self._args, **self._kwargs)
  File "/Users/admin/Desktop/Github/SPDApiNetwork/tools/blacklist2/query.py", line 20, in task
  File "/Users/admin/Desktop/Github/SPDApiNetwork/tools/blacklist2/query.py", line 20, in task
    self._target(*self._args, **self._kwargs)
  File "/Users/admin/Desktop/Github/SPDApiNetwork/tools/blacklist2/query.py", line 20, in task
    self._target(*self._args, **self._kwargs)
  File "/Users/admin/Desktop/Github/SPDApiNetwork/tools/blacklist2/query.py", line 20, in task
    conn = self.postgresql_handler.pool.getconn()
  File "/opt/homebrew/lib/python3.10/site-packages/psycopg2/pool.py", line 169, in getconn
    conn = self.postgresql_handler.pool.getconn()
  File "/opt/homebrew/lib/python3.10/site-packages/psycopg2/pool.py", line 169, in getconn
    conn = self.postgresql_handler.pool.getconn()
  File "/opt/homebrew/lib/python3.10/site-packages/psycopg2/pool.py", line 169, in getconn
    return self._getconn(key)
  File "/opt/homebrew/lib/python3.10/site-packages/psycopg2/pool.py", line 92, in _getconn
    return self._getconn(key)
  File "/opt/homebrew/lib/python3.10/site-packages/psycopg2/pool.py", line 92, in _getconn
    conn = self.postgresql_handler.pool.getconn()
  File "/opt/homebrew/lib/python3.10/site-packages/psycopg2/pool.py", line 169, in getconn
    return self._getconn(key)
  File "/opt/homebrew/lib/python3.10/site-packages/psycopg2/pool.py", line 92, in _getconn
    return self._getconn(key)
  File "/opt/homebrew/lib/python3.10/site-packages/psycopg2/pool.py", line 92, in _getconn
    raise PoolError("connection pool exhausted")
    raise PoolError("connection pool exhausted")
psycopg2.pool.PoolError: connection pool exhausted
    raise PoolError("connection pool exhausted")
psycopg2.pool.PoolError: connection pool exhausted
    raise PoolError("connection pool exhausted")
psycopg2.pool.PoolError: connection pool exhausted
psycopg2.pool.PoolError: connection pool exhausted
Exception in thread Thread-92 (task):
Traceback (most recent call last):
  File "/opt/homebrew/Cellar/python@3.10/3.10.15/Frameworks/Python.framework/Versions/3.10/lib/python3.10/threading.py", line 1016, in _bootstrap_inner
    self.run()
  File "/opt/homebrew/Cellar/python@3.10/3.10.15/Frameworks/Python.framework/Versions/3.10/lib/python3.10/threading.py", line 953, in run
    self._target(*self._args, **self._kwargs)
  File "/Users/admin/Desktop/Github/SPDApiNetwork/tools/blacklist2/query.py", line 20, in task
    conn = self.postgresql_handler.pool.getconn()
  File "/opt/homebrew/lib/python3.10/site-packages/psycopg2/pool.py", line 169, in getconn
    return self._getconn(key)
  File "/opt/homebrew/lib/python3.10/site-packages/psycopg2/pool.py", line 92, in _getconn
    raise PoolError("connection pool exhausted")
psycopg2.pool.PoolError: connection pool exhausted
Exception in thread Thread-93 (task):
Traceback (most recent call last):
  File "/opt/homebrew/Cellar/python@3.10/3.10.15/Frameworks/Python.framework/Versions/3.10/lib/python3.10/threading.py", line 1016, in _bootstrap_inner
    self.run()
  File "/opt/homebrew/Cellar/python@3.10/3.10.15/Frameworks/Python.framework/Versions/3.10/lib/python3.10/threading.py", line 953, in run
    self._target(*self._args, **self._kwargs)
  File "/Users/admin/Desktop/Github/SPDApiNetwork/tools/blacklist2/query.py", line 20, in task
    conn = self.postgresql_handler.pool.getconn()
  File "/opt/homebrew/lib/python3.10/site-packages/psycopg2/pool.py", line 169, in getconn
    return self._getconn(key)
  File "/opt/homebrew/lib/python3.10/site-packages/psycopg2/pool.py", line 92, in _getconn
    raise PoolError("connection pool exhausted")
psycopg2.pool.PoolError: connection pool exhausted
Exception in thread Thread-94 (task):
Traceback (most recent call last):
  File "/opt/homebrew/Cellar/python@3.10/3.10.15/Frameworks/Python.framework/Versions/3.10/lib/python3.10/threading.py", line 1016, in _bootstrap_inner
    self.run()
  File "/opt/homebrew/Cellar/python@3.10/3.10.15/Frameworks/Python.framework/Versions/3.10/lib/python3.10/threading.py", line 953, in run
    self._target(*self._args, **self._kwargs)
  File "/Users/admin/Desktop/Github/SPDApiNetwork/tools/blacklist2/query.py", line 20, in task
    conn = self.postgresql_handler.pool.getconn()
  File "/opt/homebrew/lib/python3.10/site-packages/psycopg2/pool.py", line 169, in getconn
    return self._getconn(key)
  File "/opt/homebrew/lib/python3.10/site-packages/psycopg2/pool.py", line 92, in _getconn
    raise PoolError("connection pool exhausted")
psycopg2.pool.PoolError: connection pool exhausted
Exception in thread Thread-95 (task):
Traceback (most recent call last):
  File "/opt/homebrew/Cellar/python@3.10/3.10.15/Frameworks/Python.framework/Versions/3.10/lib/python3.10/threading.py", line 1016, in _bootstrap_inner
    self.run()
  File "/opt/homebrew/Cellar/python@3.10/3.10.15/Frameworks/Python.framework/Versions/3.10/lib/python3.10/threading.py", line 953, in run
    self._target(*self._args, **self._kwargs)
  File "/Users/admin/Desktop/Github/SPDApiNetwork/tools/blacklist2/query.py", line 20, in task
    conn = self.postgresql_handler.pool.getconn()
  File "/opt/homebrew/lib/python3.10/site-packages/psycopg2/pool.py", line 169, in getconn
    return self._getconn(key)
  File "/opt/homebrew/lib/python3.10/site-packages/psycopg2/pool.py", line 92, in _getconn
    raise PoolError("connection pool exhausted")
psycopg2.pool.PoolError: connection pool exhausted
Exception in thread Thread-96 (task):
Traceback (most recent call last):
  File "/opt/homebrew/Cellar/python@3.10/3.10.15/Frameworks/Python.framework/Versions/3.10/lib/python3.10/threading.py", line 1016, in _bootstrap_inner
    self.run()
  File "/opt/homebrew/Cellar/python@3.10/3.10.15/Frameworks/Python.framework/Versions/3.10/lib/python3.10/threading.py", line 953, in run
    self._target(*self._args, **self._kwargs)
  File "/Users/admin/Desktop/Github/SPDApiNetwork/tools/blacklist2/query.py", line 20, in task
    conn = self.postgresql_handler.pool.getconn()
  File "/opt/homebrew/lib/python3.10/site-packages/psycopg2/pool.py", line 169, in getconn
Exception in thread Thread-97 (task):
Exception in thread Thread-98 (task):
Traceback (most recent call last):
Traceback (most recent call last):
  File "/opt/homebrew/Cellar/python@3.10/3.10.15/Frameworks/Python.framework/Versions/3.10/lib/python3.10/threading.py", line 1016, in _bootstrap_inner
    return self._getconn(key)
  File "/opt/homebrew/lib/python3.10/site-packages/psycopg2/pool.py", line 92, in _getconn
  File "/opt/homebrew/Cellar/python@3.10/3.10.15/Frameworks/Python.framework/Versions/3.10/lib/python3.10/threading.py", line 1016, in _bootstrap_inner
    self.run()
  File "/opt/homebrew/Cellar/python@3.10/3.10.15/Frameworks/Python.framework/Versions/3.10/lib/python3.10/threading.py", line 953, in run
    raise PoolError("connection pool exhausted")
psycopg2.pool.PoolError: connection pool exhausted
Exception in thread Thread-99 (task):
Traceback (most recent call last):
  File "/opt/homebrew/Cellar/python@3.10/3.10.15/Frameworks/Python.framework/Versions/3.10/lib/python3.10/threading.py", line 1016, in _bootstrap_inner
    self.run()
  File "/opt/homebrew/Cellar/python@3.10/3.10.15/Frameworks/Python.framework/Versions/3.10/lib/python3.10/threading.py", line 953, in run
    self.run()
  File "/opt/homebrew/Cellar/python@3.10/3.10.15/Frameworks/Python.framework/Versions/3.10/lib/python3.10/threading.py", line 953, in run
    self._target(*self._args, **self._kwargs)
  File "/Users/admin/Desktop/Github/SPDApiNetwork/tools/blacklist2/query.py", line 20, in task
    self._target(*self._args, **self._kwargs)
  File "/Users/admin/Desktop/Github/SPDApiNetwork/tools/blacklist2/query.py", line 20, in task
    self._target(*self._args, **self._kwargs)
  File "/Users/admin/Desktop/Github/SPDApiNetwork/tools/blacklist2/query.py", line 20, in task
    conn = self.postgresql_handler.pool.getconn()
  File "/opt/homebrew/lib/python3.10/site-packages/psycopg2/pool.py", line 169, in getconn
    conn = self.postgresql_handler.pool.getconn()
  File "/opt/homebrew/lib/python3.10/site-packages/psycopg2/pool.py", line 169, in getconn
    conn = self.postgresql_handler.pool.getconn()
  File "/opt/homebrew/lib/python3.10/site-packages/psycopg2/pool.py", line 169, in getconn
    return self._getconn(key)
  File "/opt/homebrew/lib/python3.10/site-packages/psycopg2/pool.py", line 92, in _getconn
    raise PoolError("connection pool exhausted")
psycopg2.pool.PoolError: connection pool exhausted
    return self._getconn(key)
  File "/opt/homebrew/lib/python3.10/site-packages/psycopg2/pool.py", line 92, in _getconn
    return self._getconn(key)
  File "/opt/homebrew/lib/python3.10/site-packages/psycopg2/pool.py", line 92, in _getconn
    raise PoolError("connection pool exhausted")
    raise PoolError("connection pool exhausted")
psycopg2.pool.PoolError: connection pool exhausted
psycopg2.pool.PoolError: connection pool exhausted
[94mℹ️ Bilgi: Görev işleniyor: !!python/tuple
- 272
- 37.123.97.28
- Barracuda
- b.barracudacentral.org
- pending
- '2024-12-04'
[0m
[94mℹ️ Bilgi: IP kara listede değil, kayıt yapılmayacak.[0m
[94mℹ️ Bilgi: Görev işleniyor: !!python/tuple
- 273
- 37.123.97.28
- SORBS
- dnsbl.sorbs.net
- pending
- '2024-12-04'
[0m
[94mℹ️ Bilgi: IP kara listede değil, kayıt yapılmayacak.[0m
[94mℹ️ Bilgi: Görev işleniyor: !!python/tuple
- 274
- 37.123.97.28
- SpamCop
- bl.spamcop.net
- pending
- '2024-12-04'
[0m
[94mℹ️ Bilgi: IP kara listede değil, kayıt yapılmayacak.[0m
[94mℹ️ Bilgi: Görev işleniyor: !!python/tuple
- 275
- 37.123.97.28
- The CBL
- cbl.abuseat.org
- pending
- '2024-12-04'
[0m
[94mℹ️ Bilgi: IP kara listede değil, kayıt yapılmayacak.[0m
[94mℹ️ Bilgi: Görev işleniyor: !!python/tuple
- 276
- 37.123.97.28
- SURBL
- multi.uribl.com
- pending
- '2024-12-04'
[0m
[94mℹ️ Bilgi: IP kara listede değil, kayıt yapılmayacak.[0m
[94mℹ️ Bilgi: Görev işleniyor: !!python/tuple
- 277
- 37.123.97.28
- MultiRBL
- multi.surbl.org
- pending
- '2024-12-04'
[0m
[94mℹ️ Bilgi: IP kara listede değil, kayıt yapılmayacak.[0m
[94mℹ️ Bilgi: Görev işleniyor: !!python/tuple
- 278
- 37.123.97.28
- Hostkarma
- karma.junkemailfilter.com
- pending
- '2024-12-04'
[0m
[94mℹ️ Bilgi: IP kara listede değil, kayıt yapılmayacak.[0m
[94mℹ️ Bilgi: Görev işleniyor: !!python/tuple
- 279
- 37.123.97.28
- Spamhaus DROP
- drop.spamhaus.org
- pending
- '2024-12-04'
[0m
[94mℹ️ Bilgi: IP kara listede değil, kayıt yapılmayacak.[0m
[94mℹ️ Bilgi: Görev işleniyor: !!python/tuple
- 280
- 37.123.97.28
- Spamhaus EDROP
- edrop.spamhaus.org
- pending
- '2024-12-04'
[0m
[94mℹ️ Bilgi: IP kara listede değil, kayıt yapılmayacak.[0m
[94mℹ️ Bilgi: Görev işleniyor: !!python/tuple
- 281
- 37.123.97.29
- Spamhaus
- zen.spamhaus.org
- pending
- '2024-12-04'
[0m
[94mℹ️ Bilgi: IP kara listede değil, kayıt yapılmayacak.[0m
[94mℹ️ Bilgi: Görev işleniyor: !!python/tuple
- 282
- 37.123.97.29
- Barracuda
- b.barracudacentral.org
- pending
- '2024-12-04'
[0m
[94mℹ️ Bilgi: IP kara listede değil, kayıt yapılmayacak.[0m
[94mℹ️ Bilgi: Görev işleniyor: !!python/tuple
- 283
- 37.123.97.29
- SORBS
- dnsbl.sorbs.net
- pending
- '2024-12-04'
[0m
[94mℹ️ Bilgi: IP kara listede değil, kayıt yapılmayacak.[0m
[94mℹ️ Bilgi: Görev işleniyor: !!python/tuple
- 284
- 37.123.97.29
- SpamCop
- bl.spamcop.net
- pending
- '2024-12-04'
[0m
[94mℹ️ Bilgi: IP kara listede değil, kayıt yapılmayacak.[0m
[94mℹ️ Bilgi: Görev işleniyor: !!python/tuple
- 285
- 37.123.97.29
- The CBL
- cbl.abuseat.org
- pending
- '2024-12-04'
[0m
[94mℹ️ Bilgi: IP kara listede değil, kayıt yapılmayacak.[0m
[94mℹ️ Bilgi: Görev işleniyor: !!python/tuple
- 286
- 37.123.97.29
- SURBL
- multi.uribl.com
- pending
- '2024-12-04'
[0m
[94mℹ️ Bilgi: IP kara listede değil, kayıt yapılmayacak.[0m
[94mℹ️ Bilgi: Görev işleniyor: !!python/tuple
- 287
- 37.123.97.29
- MultiRBL
- multi.surbl.org
- pending
- '2024-12-04'
[0m
[94mℹ️ Bilgi: IP kara listede değil, kayıt yapılmayacak.[0m
[94mℹ️ Bilgi: Görev işleniyor: !!python/tuple
- 288
- 37.123.97.29
- Hostkarma
- karma.junkemailfilter.com
- pending
- '2024-12-04'
[0m
[94mℹ️ Bilgi: IP kara listede değil, kayıt yapılmayacak.[0m
[94mℹ️ Bilgi: Görev işleniyor: !!python/tuple
- 289
- 37.123.97.29
- Spamhaus DROP
- drop.spamhaus.org
- pending
- '2024-12-04'
[0m
[94mℹ️ Bilgi: IP kara listede değil, kayıt yapılmayacak.[0m
[94mℹ️ Bilgi: Görev işleniyor: !!python/tuple
- 290
- 37.123.97.29
- Spamhaus EDROP
- edrop.spamhaus.org
- pending
- '2024-12-04'
[0m
[94mℹ️ Bilgi: IP kara listede değil, kayıt yapılmayacak.[0m
[94mℹ️ Bilgi: Görev işleniyor: !!python/tuple
- 291
- 37.123.97.30
- Spamhaus
- zen.spamhaus.org
- pending
- '2024-12-04'
[0m
[94mℹ️ Bilgi: IP kara listede değil, kayıt yapılmayacak.[0m
[94mℹ️ Bilgi: Görev işleniyor: !!python/tuple
- 292
- 37.123.97.30
- Barracuda
- b.barracudacentral.org
- pending
- '2024-12-04'
[0m
[94mℹ️ Bilgi: IP kara listede değil, kayıt yapılmayacak.[0m
[94mℹ️ Bilgi: Görev işleniyor: !!python/tuple
- 293
- 37.123.97.30
- SORBS
- dnsbl.sorbs.net
- pending
- '2024-12-04'
[0m
[94mℹ️ Bilgi: IP kara listede değil, kayıt yapılmayacak.[0m
[94mℹ️ Bilgi: Görev işleniyor: !!python/tuple
- 294
- 37.123.97.30
- SpamCop
- bl.spamcop.net
- pending
- '2024-12-04'
[0m
[94mℹ️ Bilgi: IP kara listede değil, kayıt yapılmayacak.[0m
[94mℹ️ Bilgi: Görev işleniyor: !!python/tuple
- 295
- 37.123.97.30
- The CBL
- cbl.abuseat.org
- pending
- '2024-12-04'
[0m
[94mℹ️ Bilgi: IP kara listede değil, kayıt yapılmayacak.[0m
[94mℹ️ Bilgi: Görev işleniyor: !!python/tuple
- 296
- 37.123.97.30
- SURBL
- multi.uribl.com
- pending
- '2024-12-04'
[0m
[94mℹ️ Bilgi: IP kara listede değil, kayıt yapılmayacak.[0m
[94mℹ️ Bilgi: Görev işleniyor: !!python/tuple
- 297
- 37.123.97.30
- MultiRBL
- multi.surbl.org
- pending
- '2024-12-04'
[0m
[94mℹ️ Bilgi: IP kara listede değil, kayıt yapılmayacak.[0m
[94mℹ️ Bilgi: Görev işleniyor: !!python/tuple
- 298
- 37.123.97.30
- Hostkarma
- karma.junkemailfilter.com
- pending
- '2024-12-04'
[0m
[94mℹ️ Bilgi: IP kara listede değil, kayıt yapılmayacak.[0m
[94mℹ️ Bilgi: Görev işleniyor: !!python/tuple
- 299
- 37.123.97.30
- Spamhaus DROP
- drop.spamhaus.org
- pending
- '2024-12-04'
[0m
[94mℹ️ Bilgi: IP kara listede değil, kayıt yapılmayacak.[0m
[94mℹ️ Bilgi: Görev işleniyor: !!python/tuple
- 300
- 37.123.97.30
- Spamhaus EDROP
- edrop.spamhaus.org
- pending
- '2024-12-04'
[0m
[94mℹ️ Bilgi: IP kara listede değil, kayıt yapılmayacak.[0m
[94mℹ️ Bilgi: Görev işleniyor: !!python/tuple
- 301
- 37.123.97.31
- Spamhaus
- zen.spamhaus.org
- pending
- '2024-12-04'
[0m
[94mℹ️ Bilgi: IP kara listede değil, kayıt yapılmayacak.[0m
[94mℹ️ Bilgi: Görev işleniyor: !!python/tuple
- 302
- 37.123.97.31
- Barracuda
- b.barracudacentral.org
- pending
- '2024-12-04'
[0m
[94mℹ️ Bilgi: IP kara listede değil, kayıt yapılmayacak.[0m
[94mℹ️ Bilgi: Görev işleniyor: !!python/tuple
- 303
- 37.123.97.31
- SORBS
- dnsbl.sorbs.net
- pending
- '2024-12-04'
[0m
[94mℹ️ Bilgi: IP kara listede değil, kayıt yapılmayacak.[0m
[94mℹ️ Bilgi: Görev işleniyor: !!python/tuple
- 304
- 37.123.97.31
- SpamCop
- bl.spamcop.net
- pending
- '2024-12-04'
[0m
[94mℹ️ Bilgi: IP kara listede değil, kayıt yapılmayacak.[0m
[94mℹ️ Bilgi: Görev işleniyor: !!python/tuple
- 305
- 37.123.97.31
- The CBL
- cbl.abuseat.org
- pending
- '2024-12-04'
[0m
[94mℹ️ Bilgi: IP kara listede değil, kayıt yapılmayacak.[0m
[94mℹ️ Bilgi: Görev işleniyor: !!python/tuple
- 306
- 37.123.97.31
- SURBL
- multi.uribl.com
- pending
- '2024-12-04'
[0m
[94mℹ️ Bilgi: IP kara listede değil, kayıt yapılmayacak.[0m
[94mℹ️ Bilgi: Görev işleniyor: !!python/tuple
- 307
- 37.123.97.31
- MultiRBL
- multi.surbl.org
- pending
- '2024-12-04'
[0m
[94mℹ️ Bilgi: IP kara listede değil, kayıt yapılmayacak.[0m
[94mℹ️ Bilgi: Görev işleniyor: !!python/tuple
- 308
- 37.123.97.31
- Hostkarma
- karma.junkemailfilter.com
- pending
- '2024-12-04'
[0m
[94mℹ️ Bilgi: IP kara listede değil, kayıt yapılmayacak.[0m
[94mℹ️ Bilgi: Görev işleniyor: !!python/tuple
- 309
- 37.123.97.31
- Spamhaus DROP
- drop.spamhaus.org
- pending
- '2024-12-04'
[0m
[94mℹ️ Bilgi: IP kara listede değil, kayıt yapılmayacak.[0m
[94mℹ️ Bilgi: Görev işleniyor: !!python/tuple
- 310
- 37.123.97.31
- Spamhaus EDROP
- edrop.spamhaus.org
- pending
- '2024-12-04'
[0m
[94mℹ️ Bilgi: IP kara listede değil, kayıt yapılmayacak.[0m
[94mℹ️ Bilgi: Görev işleniyor: !!python/tuple
- 311
- 37.123.97.32
- Spamhaus
- zen.spamhaus.org
- pending
- '2024-12-04'
[0m
[94mℹ️ Bilgi: IP kara listede değil, kayıt yapılmayacak.[0m
Exception in thread Thread-100 (task):
Traceback (most recent call last):
  File "/opt/homebrew/Cellar/python@3.10/3.10.15/Frameworks/Python.framework/Versions/3.10/lib/python3.10/threading.py", line 1016, in _bootstrap_inner
    self.run()
  File "/opt/homebrew/Cellar/python@3.10/3.10.15/Frameworks/Python.framework/Versions/3.10/lib/python3.10/threading.py", line 953, in run
    self._target(*self._args, **self._kwargs)
  File "/Users/admin/Desktop/Github/SPDApiNetwork/tools/blacklist2/query.py", line 20, in task
    conn = self.postgresql_handler.pool.getconn()
  File "/opt/homebrew/lib/python3.10/site-packages/psycopg2/pool.py", line 169, in getconn
    return self._getconn(key)
  File "/opt/homebrew/lib/python3.10/site-packages/psycopg2/pool.py", line 92, in _getconn
    raise PoolError("connection pool exhausted")
psycopg2.pool.PoolError: connection pool exhausted
Exception in thread Thread-101 (task):
Traceback (most recent call last):
  File "/opt/homebrew/Cellar/python@3.10/3.10.15/Frameworks/Python.framework/Versions/3.10/lib/python3.10/threading.py", line 1016, in _bootstrap_inner
    self.run()
  File "/opt/homebrew/Cellar/python@3.10/3.10.15/Frameworks/Python.framework/Versions/3.10/lib/python3.10/threading.py", line 953, in run
    self._target(*self._args, **self._kwargs)
  File "/Users/admin/Desktop/Github/SPDApiNetwork/tools/blacklist2/query.py", line 20, in task
    conn = self.postgresql_handler.pool.getconn()
  File "/opt/homebrew/lib/python3.10/site-packages/psycopg2/pool.py", line 169, in getconn
    return self._getconn(key)
  File "/opt/homebrew/lib/python3.10/site-packages/psycopg2/pool.py", line 92, in _getconn
    raise PoolError("connection pool exhausted")
psycopg2.pool.PoolError: connection pool exhausted
Exception in thread Thread-102 (task):
Traceback (most recent call last):
  File "/opt/homebrew/Cellar/python@3.10/3.10.15/Frameworks/Python.framework/Versions/3.10/lib/python3.10/threading.py", line 1016, in _bootstrap_inner
    self.run()
  File "/opt/homebrew/Cellar/python@3.10/3.10.15/Frameworks/Python.framework/Versions/3.10/lib/python3.10/threading.py", line 953, in run
    self._target(*self._args, **self._kwargs)
  File "/Users/admin/Desktop/Github/SPDApiNetwork/tools/blacklist2/query.py", line 20, in task
    conn = self.postgresql_handler.pool.getconn()
  File "/opt/homebrew/lib/python3.10/site-packages/psycopg2/pool.py", line 169, in getconn
    return self._getconn(key)
  File "/opt/homebrew/lib/python3.10/site-packages/psycopg2/pool.py", line 92, in _getconn
    raise PoolError("connection pool exhausted")
psycopg2.pool.PoolError: connection pool exhausted
Exception in thread Thread-103 (task):
Traceback (most recent call last):
  File "/opt/homebrew/Cellar/python@3.10/3.10.15/Frameworks/Python.framework/Versions/3.10/lib/python3.10/threading.py", line 1016, in _bootstrap_inner
    self.run()
  File "/opt/homebrew/Cellar/python@3.10/3.10.15/Frameworks/Python.framework/Versions/3.10/lib/python3.10/threading.py", line 953, in run
    self._target(*self._args, **self._kwargs)
  File "/Users/admin/Desktop/Github/SPDApiNetwork/tools/blacklist2/query.py", line 20, in task
    conn = self.postgresql_handler.pool.getconn()
  File "/opt/homebrew/lib/python3.10/site-packages/psycopg2/pool.py", line 169, in getconn
    return self._getconn(key)
  File "/opt/homebrew/lib/python3.10/site-packages/psycopg2/pool.py", line 92, in _getconn
    raise PoolError("connection pool exhausted")
psycopg2.pool.PoolError: connection pool exhausted
Exception in thread Thread-104 (task):
Traceback (most recent call last):
  File "/opt/homebrew/Cellar/python@3.10/3.10.15/Frameworks/Python.framework/Versions/3.10/lib/python3.10/threading.py", line 1016, in _bootstrap_inner
    self.run()
  File "/opt/homebrew/Cellar/python@3.10/3.10.15/Frameworks/Python.framework/Versions/3.10/lib/python3.10/threading.py", line 953, in run
    self._target(*self._args, **self._kwargs)
  File "/Users/admin/Desktop/Github/SPDApiNetwork/tools/blacklist2/query.py", line 20, in task
    conn = self.postgresql_handler.pool.getconn()
  File "/opt/homebrew/lib/python3.10/site-packages/psycopg2/pool.py", line 169, in getconn
    return self._getconn(key)
  File "/opt/homebrew/lib/python3.10/site-packages/psycopg2/pool.py", line 92, in _getconn
    raise PoolError("connection pool exhausted")
psycopg2.pool.PoolError: connection pool exhausted
Exception in thread Thread-105 (task):
Traceback (most recent call last):
  File "/opt/homebrew/Cellar/python@3.10/3.10.15/Frameworks/Python.framework/Versions/3.10/lib/python3.10/threading.py", line 1016, in _bootstrap_inner
    self.run()
  File "/opt/homebrew/Cellar/python@3.10/3.10.15/Frameworks/Python.framework/Versions/3.10/lib/python3.10/threading.py", line 953, in run
    self._target(*self._args, **self._kwargs)
  File "/Users/admin/Desktop/Github/SPDApiNetwork/tools/blacklist2/query.py", line 20, in task
    conn = self.postgresql_handler.pool.getconn()
  File "/opt/homebrew/lib/python3.10/site-packages/psycopg2/pool.py", line 169, in getconn
    return self._getconn(key)
  File "/opt/homebrew/lib/python3.10/site-packages/psycopg2/pool.py", line 92, in _getconn
    raise PoolError("connection pool exhausted")
psycopg2.pool.PoolError: connection pool exhausted
Exception in thread Thread-106 (task):
Traceback (most recent call last):
  File "/opt/homebrew/Cellar/python@3.10/3.10.15/Frameworks/Python.framework/Versions/3.10/lib/python3.10/threading.py", line 1016, in _bootstrap_inner
    self.run()
  File "/opt/homebrew/Cellar/python@3.10/3.10.15/Frameworks/Python.framework/Versions/3.10/lib/python3.10/threading.py", line 953, in run
    self._target(*self._args, **self._kwargs)
  File "/Users/admin/Desktop/Github/SPDApiNetwork/tools/blacklist2/query.py", line 20, in task
    conn = self.postgresql_handler.pool.getconn()
  File "/opt/homebrew/lib/python3.10/site-packages/psycopg2/pool.py", line 169, in getconn
    return self._getconn(key)
  File "/opt/homebrew/lib/python3.10/site-packages/psycopg2/pool.py", line 92, in _getconn
    raise PoolError("connection pool exhausted")
psycopg2.pool.PoolError: connection pool exhausted
Exception in thread Thread-70 (task):
Traceback (most recent call last):
  File "/opt/homebrew/Cellar/python@3.10/3.10.15/Frameworks/Python.framework/Versions/3.10/lib/python3.10/threading.py", line 1016, in _bootstrap_inner
Exception in thread Thread-107 (task):
Traceback (most recent call last):
  File "/opt/homebrew/Cellar/python@3.10/3.10.15/Frameworks/Python.framework/Versions/3.10/lib/python3.10/threading.py", line 1016, in _bootstrap_inner
    self.run()
  File "/opt/homebrew/Cellar/python@3.10/3.10.15/Frameworks/Python.framework/Versions/3.10/lib/python3.10/threading.py", line 953, in run
    self.run()
  File "/opt/homebrew/Cellar/python@3.10/3.10.15/Frameworks/Python.framework/Versions/3.10/lib/python3.10/threading.py", line 953, in run
    self._target(*self._args, **self._kwargs)
  File "/Users/admin/Desktop/Github/SPDApiNetwork/tools/blacklist2/query.py", line 20, in task
    self._target(*self._args, **self._kwargs)
  File "/Users/admin/Desktop/Github/SPDApiNetwork/tools/blacklist2/query.py", line 20, in task
    conn = self.postgresql_handler.pool.getconn()
  File "/opt/homebrew/lib/python3.10/site-packages/psycopg2/pool.py", line 169, in getconn
    conn = self.postgresql_handler.pool.getconn()
  File "/opt/homebrew/lib/python3.10/site-packages/psycopg2/pool.py", line 169, in getconn
    return self._getconn(key)
  File "/opt/homebrew/lib/python3.10/site-packages/psycopg2/pool.py", line 92, in _getconn
    return self._getconn(key)
  File "/opt/homebrew/lib/python3.10/site-packages/psycopg2/pool.py", line 92, in _getconn
    raise PoolError("connection pool exhausted")
psycopg2.pool.PoolError: connection pool exhausted
    raise PoolError("connection pool exhausted")
psycopg2.pool.PoolError: connection pool exhausted
Exception in thread Thread-108 (task):
Traceback (most recent call last):
  File "/opt/homebrew/Cellar/python@3.10/3.10.15/Frameworks/Python.framework/Versions/3.10/lib/python3.10/threading.py", line 1016, in _bootstrap_inner
    self.run()
  File "/opt/homebrew/Cellar/python@3.10/3.10.15/Frameworks/Python.framework/Versions/3.10/lib/python3.10/threading.py", line 953, in run
    self._target(*self._args, **self._kwargs)
  File "/Users/admin/Desktop/Github/SPDApiNetwork/tools/blacklist2/query.py", line 20, in task
    conn = self.postgresql_handler.pool.getconn()
  File "/opt/homebrew/lib/python3.10/site-packages/psycopg2/pool.py", line 169, in getconn
    return self._getconn(key)
  File "/opt/homebrew/lib/python3.10/site-packages/psycopg2/pool.py", line 92, in _getconn
    raise PoolError("connection pool exhausted")
psycopg2.pool.PoolError: connection pool exhausted
Exception in thread Thread-109 (task):
Traceback (most recent call last):
  File "/opt/homebrew/Cellar/python@3.10/3.10.15/Frameworks/Python.framework/Versions/3.10/lib/python3.10/threading.py", line 1016, in _bootstrap_inner
    self.run()
  File "/opt/homebrew/Cellar/python@3.10/3.10.15/Frameworks/Python.framework/Versions/3.10/lib/python3.10/threading.py", line 953, in run
    self._target(*self._args, **self._kwargs)
  File "/Users/admin/Desktop/Github/SPDApiNetwork/tools/blacklist2/query.py", line 20, in task
    conn = self.postgresql_handler.pool.getconn()
  File "/opt/homebrew/lib/python3.10/site-packages/psycopg2/pool.py", line 169, in getconn
    return self._getconn(key)
  File "/opt/homebrew/lib/python3.10/site-packages/psycopg2/pool.py", line 92, in _getconn
    raise PoolError("connection pool exhausted")
psycopg2.pool.PoolError: connection pool exhausted
Exception in thread Thread-77 (task):
Traceback (most recent call last):
  File "/opt/homebrew/Cellar/python@3.10/3.10.15/Frameworks/Python.framework/Versions/3.10/lib/python3.10/threading.py", line 1016, in _bootstrap_inner
Exception in thread Thread-110 (task):
Traceback (most recent call last):
  File "/opt/homebrew/Cellar/python@3.10/3.10.15/Frameworks/Python.framework/Versions/3.10/lib/python3.10/threading.py", line 1016, in _bootstrap_inner
    self.run()
  File "/opt/homebrew/Cellar/python@3.10/3.10.15/Frameworks/Python.framework/Versions/3.10/lib/python3.10/threading.py", line 953, in run
    self.run()
  File "/opt/homebrew/Cellar/python@3.10/3.10.15/Frameworks/Python.framework/Versions/3.10/lib/python3.10/threading.py", line 953, in run
    self._target(*self._args, **self._kwargs)
  File "/Users/admin/Desktop/Github/SPDApiNetwork/tools/blacklist2/query.py", line 20, in task
    self._target(*self._args, **self._kwargs)
  File "/Users/admin/Desktop/Github/SPDApiNetwork/tools/blacklist2/query.py", line 20, in task
    conn = self.postgresql_handler.pool.getconn()
  File "/opt/homebrew/lib/python3.10/site-packages/psycopg2/pool.py", line 169, in getconn
    conn = self.postgresql_handler.pool.getconn()
  File "/opt/homebrew/lib/python3.10/site-packages/psycopg2/pool.py", line 169, in getconn
    return self._getconn(key)
  File "/opt/homebrew/lib/python3.10/site-packages/psycopg2/pool.py", line 92, in _getconn
    return self._getconn(key)
  File "/opt/homebrew/lib/python3.10/site-packages/psycopg2/pool.py", line 92, in _getconn
    raise PoolError("connection pool exhausted")
    raise PoolError("connection pool exhausted")
psycopg2.pool.PoolError: connection pool exhausted
psycopg2.pool.PoolError: connection pool exhausted
Exception in thread Thread-111 (task):
Traceback (most recent call last):
  File "/opt/homebrew/Cellar/python@3.10/3.10.15/Frameworks/Python.framework/Versions/3.10/lib/python3.10/threading.py", line 1016, in _bootstrap_inner
    self.run()
  File "/opt/homebrew/Cellar/python@3.10/3.10.15/Frameworks/Python.framework/Versions/3.10/lib/python3.10/threading.py", line 953, in run
    self._target(*self._args, **self._kwargs)
  File "/Users/admin/Desktop/Github/SPDApiNetwork/tools/blacklist2/query.py", line 20, in task
    conn = self.postgresql_handler.pool.getconn()
  File "/opt/homebrew/lib/python3.10/site-packages/psycopg2/pool.py", line 169, in getconn
    return self._getconn(key)
  File "/opt/homebrew/lib/python3.10/site-packages/psycopg2/pool.py", line 92, in _getconn
    raise PoolError("connection pool exhausted")
psycopg2.pool.PoolError: connection pool exhausted
Exception in thread Thread-112 (task):
Traceback (most recent call last):
  File "/opt/homebrew/Cellar/python@3.10/3.10.15/Frameworks/Python.framework/Versions/3.10/lib/python3.10/threading.py", line 1016, in _bootstrap_inner
    self.run()
  File "/opt/homebrew/Cellar/python@3.10/3.10.15/Frameworks/Python.framework/Versions/3.10/lib/python3.10/threading.py", line 953, in run
    self._target(*self._args, **self._kwargs)
  File "/Users/admin/Desktop/Github/SPDApiNetwork/tools/blacklist2/query.py", line 20, in task
    conn = self.postgresql_handler.pool.getconn()
  File "/opt/homebrew/lib/python3.10/site-packages/psycopg2/pool.py", line 169, in getconn
    return self._getconn(key)
  File "/opt/homebrew/lib/python3.10/site-packages/psycopg2/pool.py", line 92, in _getconn
    raise PoolError("connection pool exhausted")
psycopg2.pool.PoolError: connection pool exhausted
Exception in thread Thread-113 (task):
Traceback (most recent call last):
  File "/opt/homebrew/Cellar/python@3.10/3.10.15/Frameworks/Python.framework/Versions/3.10/lib/python3.10/threading.py", line 1016, in _bootstrap_inner
    self.run()
  File "/opt/homebrew/Cellar/python@3.10/3.10.15/Frameworks/Python.framework/Versions/3.10/lib/python3.10/threading.py", line 953, in run
    self._target(*self._args, **self._kwargs)
  File "/Users/admin/Desktop/Github/SPDApiNetwork/tools/blacklist2/query.py", line 20, in task
    conn = self.postgresql_handler.pool.getconn()
  File "/opt/homebrew/lib/python3.10/site-packages/psycopg2/pool.py", line 169, in getconn
    return self._getconn(key)
  File "/opt/homebrew/lib/python3.10/site-packages/psycopg2/pool.py", line 92, in _getconn
    raise PoolError("connection pool exhausted")
psycopg2.pool.PoolError: connection pool exhausted
Exception in thread Thread-114 (task):
Traceback (most recent call last):
  File "/opt/homebrew/Cellar/python@3.10/3.10.15/Frameworks/Python.framework/Versions/3.10/lib/python3.10/threading.py", line 1016, in _bootstrap_inner
    self.run()
  File "/opt/homebrew/Cellar/python@3.10/3.10.15/Frameworks/Python.framework/Versions/3.10/lib/python3.10/threading.py", line 953, in run
    self._target(*self._args, **self._kwargs)
  File "/Users/admin/Desktop/Github/SPDApiNetwork/tools/blacklist2/query.py", line 20, in task
    conn = self.postgresql_handler.pool.getconn()
  File "/opt/homebrew/lib/python3.10/site-packages/psycopg2/pool.py", line 169, in getconn
    return self._getconn(key)
  File "/opt/homebrew/lib/python3.10/site-packages/psycopg2/pool.py", line 92, in _getconn
    raise PoolError("connection pool exhausted")
psycopg2.pool.PoolError: connection pool exhausted
Exception in thread Thread-115 (task):
Traceback (most recent call last):
  File "/opt/homebrew/Cellar/python@3.10/3.10.15/Frameworks/Python.framework/Versions/3.10/lib/python3.10/threading.py", line 1016, in _bootstrap_inner
    self.run()
  File "/opt/homebrew/Cellar/python@3.10/3.10.15/Frameworks/Python.framework/Versions/3.10/lib/python3.10/threading.py", line 953, in run
    self._target(*self._args, **self._kwargs)
  File "/Users/admin/Desktop/Github/SPDApiNetwork/tools/blacklist2/query.py", line 20, in task
    conn = self.postgresql_handler.pool.getconn()
  File "/opt/homebrew/lib/python3.10/site-packages/psycopg2/pool.py", line 169, in getconn
    return self._getconn(key)
  File "/opt/homebrew/lib/python3.10/site-packages/psycopg2/pool.py", line 92, in _getconn
    raise PoolError("connection pool exhausted")
psycopg2.pool.PoolError: connection pool exhausted
Exception in thread Thread-116 (task):
Traceback (most recent call last):
  File "/opt/homebrew/Cellar/python@3.10/3.10.15/Frameworks/Python.framework/Versions/3.10/lib/python3.10/threading.py", line 1016, in _bootstrap_inner
    self.run()
  File "/opt/homebrew/Cellar/python@3.10/3.10.15/Frameworks/Python.framework/Versions/3.10/lib/python3.10/threading.py", line 953, in run
    self._target(*self._args, **self._kwargs)
  File "/Users/admin/Desktop/Github/SPDApiNetwork/tools/blacklist2/query.py", line 20, in task
    conn = self.postgresql_handler.pool.getconn()
  File "/opt/homebrew/lib/python3.10/site-packages/psycopg2/pool.py", line 169, in getconn
    return self._getconn(key)
  File "/opt/homebrew/lib/python3.10/site-packages/psycopg2/pool.py", line 92, in _getconn
    raise PoolError("connection pool exhausted")
psycopg2.pool.PoolError: connection pool exhausted
Exception in thread Thread-117 (task):
Traceback (most recent call last):
  File "/opt/homebrew/Cellar/python@3.10/3.10.15/Frameworks/Python.framework/Versions/3.10/lib/python3.10/threading.py", line 1016, in _bootstrap_inner
    self.run()
  File "/opt/homebrew/Cellar/python@3.10/3.10.15/Frameworks/Python.framework/Versions/3.10/lib/python3.10/threading.py", line 953, in run
    self._target(*self._args, **self._kwargs)
  File "/Users/admin/Desktop/Github/SPDApiNetwork/tools/blacklist2/query.py", line 20, in task
    conn = self.postgresql_handler.pool.getconn()
  File "/opt/homebrew/lib/python3.10/site-packages/psycopg2/pool.py", line 169, in getconn
    return self._getconn(key)
  File "/opt/homebrew/lib/python3.10/site-packages/psycopg2/pool.py", line 92, in _getconn
    raise PoolError("connection pool exhausted")
psycopg2.pool.PoolError: connection pool exhausted
Exception in thread Thread-118 (task):
Traceback (most recent call last):
  File "/opt/homebrew/Cellar/python@3.10/3.10.15/Frameworks/Python.framework/Versions/3.10/lib/python3.10/threading.py", line 1016, in _bootstrap_inner
    self.run()
  File "/opt/homebrew/Cellar/python@3.10/3.10.15/Frameworks/Python.framework/Versions/3.10/lib/python3.10/threading.py", line 953, in run
    self._target(*self._args, **self._kwargs)
  File "/Users/admin/Desktop/Github/SPDApiNetwork/tools/blacklist2/query.py", line 20, in task
    conn = self.postgresql_handler.pool.getconn()
  File "/opt/homebrew/lib/python3.10/site-packages/psycopg2/pool.py", line 169, in getconn
    return self._getconn(key)
  File "/opt/homebrew/lib/python3.10/site-packages/psycopg2/pool.py", line 92, in _getconn
    raise PoolError("connection pool exhausted")
psycopg2.pool.PoolError: connection pool exhausted
Exception in thread Thread-119 (task):
Traceback (most recent call last):
  File "/opt/homebrew/Cellar/python@3.10/3.10.15/Frameworks/Python.framework/Versions/3.10/lib/python3.10/threading.py", line 1016, in _bootstrap_inner
    self.run()
  File "/opt/homebrew/Cellar/python@3.10/3.10.15/Frameworks/Python.framework/Versions/3.10/lib/python3.10/threading.py", line 953, in run
    self._target(*self._args, **self._kwargs)
  File "/Users/admin/Desktop/Github/SPDApiNetwork/tools/blacklist2/query.py", line 20, in task
    conn = self.postgresql_handler.pool.getconn()
  File "/opt/homebrew/lib/python3.10/site-packages/psycopg2/pool.py", line 169, in getconn
    return self._getconn(key)
  File "/opt/homebrew/lib/python3.10/site-packages/psycopg2/pool.py", line 92, in _getconn
    raise PoolError("connection pool exhausted")
psycopg2.pool.PoolError: connection pool exhausted
Exception in thread Thread-120 (task):
Traceback (most recent call last):
  File "/opt/homebrew/Cellar/python@3.10/3.10.15/Frameworks/Python.framework/Versions/3.10/lib/python3.10/threading.py", line 1016, in _bootstrap_inner
    self.run()
  File "/opt/homebrew/Cellar/python@3.10/3.10.15/Frameworks/Python.framework/Versions/3.10/lib/python3.10/threading.py", line 953, in run
    self._target(*self._args, **self._kwargs)
  File "/Users/admin/Desktop/Github/SPDApiNetwork/tools/blacklist2/query.py", line 20, in task
    conn = self.postgresql_handler.pool.getconn()
  File "/opt/homebrew/lib/python3.10/site-packages/psycopg2/pool.py", line 169, in getconn
    return self._getconn(key)
  File "/opt/homebrew/lib/python3.10/site-packages/psycopg2/pool.py", line 92, in _getconn
    raise PoolError("connection pool exhausted")
psycopg2.pool.PoolError: connection pool exhausted
Exception in thread Thread-121 (task):
Traceback (most recent call last):
  File "/opt/homebrew/Cellar/python@3.10/3.10.15/Frameworks/Python.framework/Versions/3.10/lib/python3.10/threading.py", line 1016, in _bootstrap_inner
    self.run()
  File "/opt/homebrew/Cellar/python@3.10/3.10.15/Frameworks/Python.framework/Versions/3.10/lib/python3.10/threading.py", line 953, in run
    self._target(*self._args, **self._kwargs)
  File "/Users/admin/Desktop/Github/SPDApiNetwork/tools/blacklist2/query.py", line 20, in task
    conn = self.postgresql_handler.pool.getconn()
  File "/opt/homebrew/lib/python3.10/site-packages/psycopg2/pool.py", line 169, in getconn
    return self._getconn(key)
  File "/opt/homebrew/lib/python3.10/site-packages/psycopg2/pool.py", line 92, in _getconn
    raise PoolError("connection pool exhausted")
psycopg2.pool.PoolError: connection pool exhausted
Exception in thread Thread-122 (task):
Traceback (most recent call last):
  File "/opt/homebrew/Cellar/python@3.10/3.10.15/Frameworks/Python.framework/Versions/3.10/lib/python3.10/threading.py", line 1016, in _bootstrap_inner
    self.run()
  File "/opt/homebrew/Cellar/python@3.10/3.10.15/Frameworks/Python.framework/Versions/3.10/lib/python3.10/threading.py", line 953, in run
    self._target(*self._args, **self._kwargs)
  File "/Users/admin/Desktop/Github/SPDApiNetwork/tools/blacklist2/query.py", line 20, in task
    conn = self.postgresql_handler.pool.getconn()
  File "/opt/homebrew/lib/python3.10/site-packages/psycopg2/pool.py", line 169, in getconn
    return self._getconn(key)
  File "/opt/homebrew/lib/python3.10/site-packages/psycopg2/pool.py", line 92, in _getconn
    raise PoolError("connection pool exhausted")
psycopg2.pool.PoolError: connection pool exhausted
Exception in thread Thread-123 (task):
Traceback (most recent call last):
  File "/opt/homebrew/Cellar/python@3.10/3.10.15/Frameworks/Python.framework/Versions/3.10/lib/python3.10/threading.py", line 1016, in _bootstrap_inner
    self.run()
  File "/opt/homebrew/Cellar/python@3.10/3.10.15/Frameworks/Python.framework/Versions/3.10/lib/python3.10/threading.py", line 953, in run
    self._target(*self._args, **self._kwargs)
  File "/Users/admin/Desktop/Github/SPDApiNetwork/tools/blacklist2/query.py", line 20, in task
    conn = self.postgresql_handler.pool.getconn()
  File "/opt/homebrew/lib/python3.10/site-packages/psycopg2/pool.py", line 169, in getconn
    return self._getconn(key)
  File "/opt/homebrew/lib/python3.10/site-packages/psycopg2/pool.py", line 92, in _getconn
    raise PoolError("connection pool exhausted")
psycopg2.pool.PoolError: connection pool exhausted
Exception in thread Thread-124 (task):
Traceback (most recent call last):
  File "/opt/homebrew/Cellar/python@3.10/3.10.15/Frameworks/Python.framework/Versions/3.10/lib/python3.10/threading.py", line 1016, in _bootstrap_inner
    self.run()
  File "/opt/homebrew/Cellar/python@3.10/3.10.15/Frameworks/Python.framework/Versions/3.10/lib/python3.10/threading.py", line 953, in run
    self._target(*self._args, **self._kwargs)
  File "/Users/admin/Desktop/Github/SPDApiNetwork/tools/blacklist2/query.py", line 20, in task
    conn = self.postgresql_handler.pool.getconn()
  File "/opt/homebrew/lib/python3.10/site-packages/psycopg2/pool.py", line 169, in getconn
    return self._getconn(key)
  File "/opt/homebrew/lib/python3.10/site-packages/psycopg2/pool.py", line 92, in _getconn
    raise PoolError("connection pool exhausted")
psycopg2.pool.PoolError: connection pool exhausted
Exception in thread Thread-125 (task):
Traceback (most recent call last):
  File "/opt/homebrew/Cellar/python@3.10/3.10.15/Frameworks/Python.framework/Versions/3.10/lib/python3.10/threading.py", line 1016, in _bootstrap_inner
    self.run()
  File "/opt/homebrew/Cellar/python@3.10/3.10.15/Frameworks/Python.framework/Versions/3.10/lib/python3.10/threading.py", line 953, in run
    self._target(*self._args, **self._kwargs)
  File "/Users/admin/Desktop/Github/SPDApiNetwork/tools/blacklist2/query.py", line 20, in task
    conn = self.postgresql_handler.pool.getconn()
  File "/opt/homebrew/lib/python3.10/site-packages/psycopg2/pool.py", line 169, in getconn
    return self._getconn(key)
  File "/opt/homebrew/lib/python3.10/site-packages/psycopg2/pool.py", line 92, in _getconn
    raise PoolError("connection pool exhausted")
psycopg2.pool.PoolError: connection pool exhausted
Exception in thread Thread-126 (task):
Traceback (most recent call last):
  File "/opt/homebrew/Cellar/python@3.10/3.10.15/Frameworks/Python.framework/Versions/3.10/lib/python3.10/threading.py", line 1016, in _bootstrap_inner
    self.run()
  File "/opt/homebrew/Cellar/python@3.10/3.10.15/Frameworks/Python.framework/Versions/3.10/lib/python3.10/threading.py", line 953, in run
    self._target(*self._args, **self._kwargs)
  File "/Users/admin/Desktop/Github/SPDApiNetwork/tools/blacklist2/query.py", line 20, in task
    conn = self.postgresql_handler.pool.getconn()
  File "/opt/homebrew/lib/python3.10/site-packages/psycopg2/pool.py", line 169, in getconn
    return self._getconn(key)
  File "/opt/homebrew/lib/python3.10/site-packages/psycopg2/pool.py", line 92, in _getconn
    raise PoolError("connection pool exhausted")
psycopg2.pool.PoolError: connection pool exhausted
Exception in thread Thread-127 (task):
Traceback (most recent call last):
  File "/opt/homebrew/Cellar/python@3.10/3.10.15/Frameworks/Python.framework/Versions/3.10/lib/python3.10/threading.py", line 1016, in _bootstrap_inner
    self.run()
  File "/opt/homebrew/Cellar/python@3.10/3.10.15/Frameworks/Python.framework/Versions/3.10/lib/python3.10/threading.py", line 953, in run
    self._target(*self._args, **self._kwargs)
  File "/Users/admin/Desktop/Github/SPDApiNetwork/tools/blacklist2/query.py", line 20, in task
    conn = self.postgresql_handler.pool.getconn()
  File "/opt/homebrew/lib/python3.10/site-packages/psycopg2/pool.py", line 169, in getconn
    return self._getconn(key)
  File "/opt/homebrew/lib/python3.10/site-packages/psycopg2/pool.py", line 92, in _getconn
    raise PoolError("connection pool exhausted")
psycopg2.pool.PoolError: connection pool exhausted
Exception in thread Thread-128 (task):
Traceback (most recent call last):
  File "/opt/homebrew/Cellar/python@3.10/3.10.15/Frameworks/Python.framework/Versions/3.10/lib/python3.10/threading.py", line 1016, in _bootstrap_inner
    self.run()
  File "/opt/homebrew/Cellar/python@3.10/3.10.15/Frameworks/Python.framework/Versions/3.10/lib/python3.10/threading.py", line 953, in run
    self._target(*self._args, **self._kwargs)
  File "/Users/admin/Desktop/Github/SPDApiNetwork/tools/blacklist2/query.py", line 20, in task
    conn = self.postgresql_handler.pool.getconn()
  File "/opt/homebrew/lib/python3.10/site-packages/psycopg2/pool.py", line 169, in getconn
    return self._getconn(key)
  File "/opt/homebrew/lib/python3.10/site-packages/psycopg2/pool.py", line 92, in _getconn
    raise PoolError("connection pool exhausted")
psycopg2.pool.PoolError: connection pool exhausted
Exception in thread Thread-129 (task):
Traceback (most recent call last):
  File "/opt/homebrew/Cellar/python@3.10/3.10.15/Frameworks/Python.framework/Versions/3.10/lib/python3.10/threading.py", line 1016, in _bootstrap_inner
    self.run()
  File "/opt/homebrew/Cellar/python@3.10/3.10.15/Frameworks/Python.framework/Versions/3.10/lib/python3.10/threading.py", line 953, in run
    self._target(*self._args, **self._kwargs)
  File "/Users/admin/Desktop/Github/SPDApiNetwork/tools/blacklist2/query.py", line 20, in task
    conn = self.postgresql_handler.pool.getconn()
  File "/opt/homebrew/lib/python3.10/site-packages/psycopg2/pool.py", line 169, in getconn
    return self._getconn(key)
  File "/opt/homebrew/lib/python3.10/site-packages/psycopg2/pool.py", line 92, in _getconn
    raise PoolError("connection pool exhausted")
psycopg2.pool.PoolError: connection pool exhausted
Exception in thread Thread-130 (task):
Traceback (most recent call last):
  File "/opt/homebrew/Cellar/python@3.10/3.10.15/Frameworks/Python.framework/Versions/3.10/lib/python3.10/threading.py", line 1016, in _bootstrap_inner
    self.run()
  File "/opt/homebrew/Cellar/python@3.10/3.10.15/Frameworks/Python.framework/Versions/3.10/lib/python3.10/threading.py", line 953, in run
    self._target(*self._args, **self._kwargs)
  File "/Users/admin/Desktop/Github/SPDApiNetwork/tools/blacklist2/query.py", line 20, in task
    conn = self.postgresql_handler.pool.getconn()
  File "/opt/homebrew/lib/python3.10/site-packages/psycopg2/pool.py", line 169, in getconn
    return self._getconn(key)
  File "/opt/homebrew/lib/python3.10/site-packages/psycopg2/pool.py", line 92, in _getconn
    raise PoolError("connection pool exhausted")
psycopg2.pool.PoolError: connection pool exhausted
Exception in thread Thread-131 (task):
Traceback (most recent call last):
  File "/opt/homebrew/Cellar/python@3.10/3.10.15/Frameworks/Python.framework/Versions/3.10/lib/python3.10/threading.py", line 1016, in _bootstrap_inner
    self.run()
  File "/opt/homebrew/Cellar/python@3.10/3.10.15/Frameworks/Python.framework/Versions/3.10/lib/python3.10/threading.py", line 953, in run
    self._target(*self._args, **self._kwargs)
  File "/Users/admin/Desktop/Github/SPDApiNetwork/tools/blacklist2/query.py", line 20, in task
    conn = self.postgresql_handler.pool.getconn()
  File "/opt/homebrew/lib/python3.10/site-packages/psycopg2/pool.py", line 169, in getconn
    return self._getconn(key)
  File "/opt/homebrew/lib/python3.10/site-packages/psycopg2/pool.py", line 92, in _getconn
    raise PoolError("connection pool exhausted")
psycopg2.pool.PoolError: connection pool exhausted
Exception in thread Thread-132 (task):
Traceback (most recent call last):
  File "/opt/homebrew/Cellar/python@3.10/3.10.15/Frameworks/Python.framework/Versions/3.10/lib/python3.10/threading.py", line 1016, in _bootstrap_inner
    self.run()
  File "/opt/homebrew/Cellar/python@3.10/3.10.15/Frameworks/Python.framework/Versions/3.10/lib/python3.10/threading.py", line 953, in run
    self._target(*self._args, **self._kwargs)
  File "/Users/admin/Desktop/Github/SPDApiNetwork/tools/blacklist2/query.py", line 20, in task
    conn = self.postgresql_handler.pool.getconn()
  File "/opt/homebrew/lib/python3.10/site-packages/psycopg2/pool.py", line 169, in getconn
    return self._getconn(key)
  File "/opt/homebrew/lib/python3.10/site-packages/psycopg2/pool.py", line 92, in _getconn
    raise PoolError("connection pool exhausted")
psycopg2.pool.PoolError: connection pool exhausted
Exception in thread Thread-133 (task):
Traceback (most recent call last):
  File "/opt/homebrew/Cellar/python@3.10/3.10.15/Frameworks/Python.framework/Versions/3.10/lib/python3.10/threading.py", line 1016, in _bootstrap_inner
    self.run()
  File "/opt/homebrew/Cellar/python@3.10/3.10.15/Frameworks/Python.framework/Versions/3.10/lib/python3.10/threading.py", line 953, in run
    self._target(*self._args, **self._kwargs)
  File "/Users/admin/Desktop/Github/SPDApiNetwork/tools/blacklist2/query.py", line 20, in task
    conn = self.postgresql_handler.pool.getconn()
  File "/opt/homebrew/lib/python3.10/site-packages/psycopg2/pool.py", line 169, in getconn
    return self._getconn(key)
  File "/opt/homebrew/lib/python3.10/site-packages/psycopg2/pool.py", line 92, in _getconn
    raise PoolError("connection pool exhausted")
psycopg2.pool.PoolError: connection pool exhausted
Exception in thread Thread-134 (task):
Traceback (most recent call last):
  File "/opt/homebrew/Cellar/python@3.10/3.10.15/Frameworks/Python.framework/Versions/3.10/lib/python3.10/threading.py", line 1016, in _bootstrap_inner
    self.run()
  File "/opt/homebrew/Cellar/python@3.10/3.10.15/Frameworks/Python.framework/Versions/3.10/lib/python3.10/threading.py", line 953, in run
    self._target(*self._args, **self._kwargs)
  File "/Users/admin/Desktop/Github/SPDApiNetwork/tools/blacklist2/query.py", line 20, in task
    conn = self.postgresql_handler.pool.getconn()
  File "/opt/homebrew/lib/python3.10/site-packages/psycopg2/pool.py", line 169, in getconn
    return self._getconn(key)
  File "/opt/homebrew/lib/python3.10/site-packages/psycopg2/pool.py", line 92, in _getconn
    raise PoolError("connection pool exhausted")
psycopg2.pool.PoolError: connection pool exhausted
Exception in thread Thread-135 (task):
Traceback (most recent call last):
  File "/opt/homebrew/Cellar/python@3.10/3.10.15/Frameworks/Python.framework/Versions/3.10/lib/python3.10/threading.py", line 1016, in _bootstrap_inner
    self.run()
  File "/opt/homebrew/Cellar/python@3.10/3.10.15/Frameworks/Python.framework/Versions/3.10/lib/python3.10/threading.py", line 953, in run
    self._target(*self._args, **self._kwargs)
  File "/Users/admin/Desktop/Github/SPDApiNetwork/tools/blacklist2/query.py", line 20, in task
    conn = self.postgresql_handler.pool.getconn()
  File "/opt/homebrew/lib/python3.10/site-packages/psycopg2/pool.py", line 169, in getconn
    return self._getconn(key)
  File "/opt/homebrew/lib/python3.10/site-packages/psycopg2/pool.py", line 92, in _getconn
    raise PoolError("connection pool exhausted")
psycopg2.pool.PoolError: connection pool exhausted
Exception in thread Thread-136 (task):
Traceback (most recent call last):
  File "/opt/homebrew/Cellar/python@3.10/3.10.15/Frameworks/Python.framework/Versions/3.10/lib/python3.10/threading.py", line 1016, in _bootstrap_inner
    self.run()
  File "/opt/homebrew/Cellar/python@3.10/3.10.15/Frameworks/Python.framework/Versions/3.10/lib/python3.10/threading.py", line 953, in run
    self._target(*self._args, **self._kwargs)
  File "/Users/admin/Desktop/Github/SPDApiNetwork/tools/blacklist2/query.py", line 20, in task
    conn = self.postgresql_handler.pool.getconn()
  File "/opt/homebrew/lib/python3.10/site-packages/psycopg2/pool.py", line 169, in getconn
    return self._getconn(key)
  File "/opt/homebrew/lib/python3.10/site-packages/psycopg2/pool.py", line 92, in _getconn
    raise PoolError("connection pool exhausted")
psycopg2.pool.PoolError: connection pool exhausted
Exception in thread Thread-137 (task):
Traceback (most recent call last):
  File "/opt/homebrew/Cellar/python@3.10/3.10.15/Frameworks/Python.framework/Versions/3.10/lib/python3.10/threading.py", line 1016, in _bootstrap_inner
    self.run()
  File "/opt/homebrew/Cellar/python@3.10/3.10.15/Frameworks/Python.framework/Versions/3.10/lib/python3.10/threading.py", line 953, in run
    self._target(*self._args, **self._kwargs)
  File "/Users/admin/Desktop/Github/SPDApiNetwork/tools/blacklist2/query.py", line 20, in task
    conn = self.postgresql_handler.pool.getconn()
  File "/opt/homebrew/lib/python3.10/site-packages/psycopg2/pool.py", line 169, in getconn
    return self._getconn(key)
  File "/opt/homebrew/lib/python3.10/site-packages/psycopg2/pool.py", line 92, in _getconn
    raise PoolError("connection pool exhausted")
psycopg2.pool.PoolError: connection pool exhausted
Exception in thread Thread-138 (task):
Traceback (most recent call last):
  File "/opt/homebrew/Cellar/python@3.10/3.10.15/Frameworks/Python.framework/Versions/3.10/lib/python3.10/threading.py", line 1016, in _bootstrap_inner
    self.run()
  File "/opt/homebrew/Cellar/python@3.10/3.10.15/Frameworks/Python.framework/Versions/3.10/lib/python3.10/threading.py", line 953, in run
    self._target(*self._args, **self._kwargs)
  File "/Users/admin/Desktop/Github/SPDApiNetwork/tools/blacklist2/query.py", line 20, in task
    conn = self.postgresql_handler.pool.getconn()
  File "/opt/homebrew/lib/python3.10/site-packages/psycopg2/pool.py", line 169, in getconn
    return self._getconn(key)
  File "/opt/homebrew/lib/python3.10/site-packages/psycopg2/pool.py", line 92, in _getconn
    raise PoolError("connection pool exhausted")
psycopg2.pool.PoolError: connection pool exhausted
Exception in thread Thread-139 (task):
Traceback (most recent call last):
  File "/opt/homebrew/Cellar/python@3.10/3.10.15/Frameworks/Python.framework/Versions/3.10/lib/python3.10/threading.py", line 1016, in _bootstrap_inner
    self.run()
  File "/opt/homebrew/Cellar/python@3.10/3.10.15/Frameworks/Python.framework/Versions/3.10/lib/python3.10/threading.py", line 953, in run
    self._target(*self._args, **self._kwargs)
  File "/Users/admin/Desktop/Github/SPDApiNetwork/tools/blacklist2/query.py", line 20, in task
    conn = self.postgresql_handler.pool.getconn()
  File "/opt/homebrew/lib/python3.10/site-packages/psycopg2/pool.py", line 169, in getconn
    return self._getconn(key)
  File "/opt/homebrew/lib/python3.10/site-packages/psycopg2/pool.py", line 92, in _getconn
    raise PoolError("connection pool exhausted")
psycopg2.pool.PoolError: connection pool exhausted
[94mℹ️ Bilgi: Görev işleniyor: !!python/tuple
- 312
- 37.123.97.32
- Barracuda
- b.barracudacentral.org
- pending
- '2024-12-04'
[0m
[94mℹ️ Bilgi: IP kara listede değil, kayıt yapılmayacak.[0m
[94mℹ️ Bilgi: Görev işleniyor: !!python/tuple
- 313
- 37.123.97.32
- SORBS
- dnsbl.sorbs.net
- pending
- '2024-12-04'
[0m
[94mℹ️ Bilgi: IP kara listede değil, kayıt yapılmayacak.[0m
[94mℹ️ Bilgi: Görev işleniyor: !!python/tuple
- 314
- 37.123.97.32
- SpamCop
- bl.spamcop.net
- pending
- '2024-12-04'
[0m
[94mℹ️ Bilgi: IP kara listede değil, kayıt yapılmayacak.[0m
[94mℹ️ Bilgi: Görev işleniyor: !!python/tuple
- 315
- 37.123.97.32
- The CBL
- cbl.abuseat.org
- pending
- '2024-12-04'
[0m
[94mℹ️ Bilgi: IP kara listede değil, kayıt yapılmayacak.[0m
[94mℹ️ Bilgi: Görev işleniyor: !!python/tuple
- 316
- 37.123.97.32
- SURBL
- multi.uribl.com
- pending
- '2024-12-04'
[0m
[94mℹ️ Bilgi: IP kara listede değil, kayıt yapılmayacak.[0m
[94mℹ️ Bilgi: Görev işleniyor: !!python/tuple
- 317
- 37.123.97.32
- MultiRBL
- multi.surbl.org
- pending
- '2024-12-04'
[0m
[94mℹ️ Bilgi: IP kara listede değil, kayıt yapılmayacak.[0m
[94mℹ️ Bilgi: Görev işleniyor: !!python/tuple
- 318
- 37.123.97.32
- Hostkarma
- karma.junkemailfilter.com
- pending
- '2024-12-04'
[0m
[94mℹ️ Bilgi: IP kara listede değil, kayıt yapılmayacak.[0m
[94mℹ️ Bilgi: Görev işleniyor: !!python/tuple
- 319
- 37.123.97.32
- Spamhaus DROP
- drop.spamhaus.org
- pending
- '2024-12-04'
[0m
[94mℹ️ Bilgi: IP kara listede değil, kayıt yapılmayacak.[0m
[94mℹ️ Bilgi: Görev işleniyor: !!python/tuple
- 320
- 37.123.97.32
- Spamhaus EDROP
- edrop.spamhaus.org
- pending
- '2024-12-04'
[0m
[94mℹ️ Bilgi: IP kara listede değil, kayıt yapılmayacak.[0m
[94mℹ️ Bilgi: Görev işleniyor: !!python/tuple
- 321
- 37.123.97.33
- Spamhaus
- zen.spamhaus.org
- pending
- '2024-12-04'
[0m
[94mℹ️ Bilgi: IP kara listede değil, kayıt yapılmayacak.[0m
[94mℹ️ Bilgi: Görev işleniyor: !!python/tuple
- 322
- 37.123.97.33
- Barracuda
- b.barracudacentral.org
- pending
- '2024-12-04'